2020-02-08 23:35:33 [scrapy.utils.log] INFO: Scrapy 1.8.0 started (bot: xxoovideo)
2020-02-08 23:35:33 [scrapy.utils.log] INFO: Versions: lxml 4.4.2.0, libxml2 2.9.9, cssselect 1.1.0, parsel 1.5.2, w3lib 1.21.0, Twisted 19.10.0, Python 3.6.9 (default, Nov  7 2019, 10:44:02) - [GCC 8.3.0], pyOpenSSL 19.1.0 (OpenSSL 1.1.1d  10 Sep 2019), cryptography 2.8, Platform Linux-5.3.0-28-generic-x86_64-with-Ubuntu-18.04-bionic
2020-02-08 23:35:33 [scrapy.crawler] INFO: Overridden settings: {'BOT_NAME': 'xxoovideo', 'NEWSPIDER_MODULE': 'xxoovideo.spiders', 'SPIDER_MODULES': ['xxoovideo.spiders'], 'USER_AGENT': 'Mozilla/5.0 (Windows NT 10.0; Win64; x64) AppleWebKit/537.36 (KHTML, like Gecko) Chrome/70.0.3538.77 Safari/537.36'}
2020-02-08 23:35:33 [scrapy.extensions.telnet] INFO: Telnet Password: bbce9367101f866d
2020-02-08 23:35:33 [scrapy.middleware] INFO: Enabled extensions:
['scrapy.extensions.corestats.CoreStats',
 'scrapy.extensions.telnet.TelnetConsole',
 'scrapy.extensions.memusage.MemoryUsage',
 'scrapy.extensions.logstats.LogStats']
2020-02-08 23:35:33 [scrapy.middleware] INFO: Enabled downloader middlewares:
['scrapy.downloadermiddlewares.httpauth.HttpAuthMiddleware',
 'scrapy.downloadermiddlewares.downloadtimeout.DownloadTimeoutMiddleware',
 'scrapy.downloadermiddlewares.defaultheaders.DefaultHeadersMiddleware',
 'scrapy.downloadermiddlewares.useragent.UserAgentMiddleware',
 'xxoovideo.middlewares.XxoovideoDownloaderMiddleware',
 'scrapy.downloadermiddlewares.retry.RetryMiddleware',
 'scrapy.downloadermiddlewares.redirect.MetaRefreshMiddleware',
 'scrapy.downloadermiddlewares.httpcompression.HttpCompressionMiddleware',
 'scrapy.downloadermiddlewares.redirect.RedirectMiddleware',
 'scrapy.downloadermiddlewares.cookies.CookiesMiddleware',
 'scrapy.downloadermiddlewares.httpproxy.HttpProxyMiddleware',
 'scrapy.downloadermiddlewares.stats.DownloaderStats']
2020-02-08 23:35:33 [scrapy.middleware] INFO: Enabled spider middlewares:
['scrapy.spidermiddlewares.httperror.HttpErrorMiddleware',
 'scrapy.spidermiddlewares.offsite.OffsiteMiddleware',
 'scrapy.spidermiddlewares.referer.RefererMiddleware',
 'scrapy.spidermiddlewares.urllength.UrlLengthMiddleware',
 'scrapy.spidermiddlewares.depth.DepthMiddleware']
2020-02-08 23:35:33 [scrapy.middleware] INFO: Enabled item pipelines:
['xxoovideo.pipelines.XxoovideoPipeline']
2020-02-08 23:35:33 [scrapy.core.engine] INFO: Spider opened
2020-02-08 23:35:33 [scrapy.extensions.logstats] INFO: Crawled 0 pages (at 0 pages/min), scraped 0 items (at 0 items/min)
2020-02-08 23:35:33 [scrapy.extensions.telnet] INFO: Telnet console listening on 127.0.0.1:6023
2020-02-08 23:35:35 [scrapy.core.engine] DEBUG: Crawled (200) <GET http://yj1.ceea3a8ea1f.pw/pw/> (referer: None)
2020-02-08 23:35:36 [scrapy.core.engine] DEBUG: Crawled (200) <GET http://yj1.ceea3a8ea1f.pw/pw/thread.php?fid=111> (referer: http://yj1.ceea3a8ea1f.pw/pw/)
2020-02-08 23:35:36 [scrapy.core.scraper] ERROR: Spider error processing <GET http://yj1.ceea3a8ea1f.pw/pw/thread.php?fid=111> (referer: http://yj1.ceea3a8ea1f.pw/pw/)
Traceback (most recent call last):
  File "/usr/local/lib/python3.6/dist-packages/scrapy/utils/defer.py", line 102, in iter_errback
    yield next(it)
  File "/usr/local/lib/python3.6/dist-packages/scrapy/core/spidermw.py", line 84, in evaluate_iterable
    for r in iterable:
  File "/usr/local/lib/python3.6/dist-packages/scrapy/spidermiddlewares/offsite.py", line 29, in process_spider_output
    for x in result:
  File "/usr/local/lib/python3.6/dist-packages/scrapy/core/spidermw.py", line 84, in evaluate_iterable
    for r in iterable:
  File "/usr/local/lib/python3.6/dist-packages/scrapy/spidermiddlewares/referer.py", line 339, in <genexpr>
    return (_set_referer(r) for r in result or ())
  File "/usr/local/lib/python3.6/dist-packages/scrapy/core/spidermw.py", line 84, in evaluate_iterable
    for r in iterable:
  File "/usr/local/lib/python3.6/dist-packages/scrapy/spidermiddlewares/urllength.py", line 37, in <genexpr>
    return (r for r in result or () if _filter(r))
  File "/usr/local/lib/python3.6/dist-packages/scrapy/core/spidermw.py", line 84, in evaluate_iterable
    for r in iterable:
  File "/usr/local/lib/python3.6/dist-packages/scrapy/spidermiddlewares/depth.py", line 58, in <genexpr>
    return (r for r in result or () if _filter(r))
  File "/home/jiangjin/桌面/xxoovideo/xxoovideo/spiders/video.py", line 32, in parse_next
    for next_link in next_links:
TypeError: 'LxmlLinkExtractor' object is not iterable
2020-02-08 23:35:36 [scrapy.core.scraper] ERROR: Error downloading <GET http://yj1.ceea3a8ea1f.pw/pw/html_data/111/2002/4599244.html>
Traceback (most recent call last):
  File "/usr/local/lib/python3.6/dist-packages/redis/connection.py", line 439, in connect
    sock = self._connect()
  File "/usr/local/lib/python3.6/dist-packages/redis/connection.py", line 494, in _connect
    raise err
  File "/usr/local/lib/python3.6/dist-packages/redis/connection.py", line 482, in _connect
    sock.connect(socket_address)
ConnectionRefusedError: [Errno 111] Connection refused

During handling of the above exception, another exception occurred:

Traceback (most recent call last):
  File "/usr/local/lib/python3.6/dist-packages/redis/client.py", line 572, in execute_command
    connection.send_command(*args)
  File "/usr/local/lib/python3.6/dist-packages/redis/connection.py", line 563, in send_command
    self.send_packed_command(self.pack_command(*args))
  File "/usr/local/lib/python3.6/dist-packages/redis/connection.py", line 538, in send_packed_command
    self.connect()
  File "/usr/local/lib/python3.6/dist-packages/redis/connection.py", line 442, in connect
    raise ConnectionError(self._error_message(e))
redis.exceptions.ConnectionError: Error 111 connecting to localhost:6379. Connection refused.

During handling of the above exception, another exception occurred:

Traceback (most recent call last):
  File "/usr/local/lib/python3.6/dist-packages/redis/connection.py", line 439, in connect
    sock = self._connect()
  File "/usr/local/lib/python3.6/dist-packages/redis/connection.py", line 494, in _connect
    raise err
  File "/usr/local/lib/python3.6/dist-packages/redis/connection.py", line 482, in _connect
    sock.connect(socket_address)
ConnectionRefusedError: [Errno 111] Connection refused

During handling of the above exception, another exception occurred:

Traceback (most recent call last):
  File "/usr/local/lib/python3.6/dist-packages/twisted/internet/defer.py", line 1418, in _inlineCallbacks
    result = g.send(result)
  File "/usr/local/lib/python3.6/dist-packages/scrapy/core/downloader/middleware.py", line 38, in process_request
    response = yield method(request=request, spider=spider)
  File "/home/jiangjin/桌面/xxoovideo/xxoovideo/middlewares.py", line 17, in process_request
    if self.bf.isContains(request.url):
  File "/home/jiangjin/桌面/xxoovideo/xxoovideo/tool/bloomfulter.py", line 50, in isContains
    ret = ret & self.server.getbit(name, loc)
  File "/usr/local/lib/python3.6/dist-packages/redis/client.py", line 894, in getbit
    return self.execute_command('GETBIT', name, offset)
  File "/usr/local/lib/python3.6/dist-packages/redis/client.py", line 578, in execute_command
    connection.send_command(*args)
  File "/usr/local/lib/python3.6/dist-packages/redis/connection.py", line 563, in send_command
    self.send_packed_command(self.pack_command(*args))
  File "/usr/local/lib/python3.6/dist-packages/redis/connection.py", line 538, in send_packed_command
    self.connect()
  File "/usr/local/lib/python3.6/dist-packages/redis/connection.py", line 442, in connect
    raise ConnectionError(self._error_message(e))
redis.exceptions.ConnectionError: Error 111 connecting to localhost:6379. Connection refused.
2020-02-08 23:35:36 [scrapy.core.scraper] ERROR: Error downloading <GET http://yj1.ceea3a8ea1f.pw/pw/html_data/111/2002/4598572.html>
Traceback (most recent call last):
  File "/usr/local/lib/python3.6/dist-packages/redis/connection.py", line 439, in connect
    sock = self._connect()
  File "/usr/local/lib/python3.6/dist-packages/redis/connection.py", line 494, in _connect
    raise err
  File "/usr/local/lib/python3.6/dist-packages/redis/connection.py", line 482, in _connect
    sock.connect(socket_address)
ConnectionRefusedError: [Errno 111] Connection refused

During handling of the above exception, another exception occurred:

Traceback (most recent call last):
  File "/usr/local/lib/python3.6/dist-packages/redis/client.py", line 572, in execute_command
    connection.send_command(*args)
  File "/usr/local/lib/python3.6/dist-packages/redis/connection.py", line 563, in send_command
    self.send_packed_command(self.pack_command(*args))
  File "/usr/local/lib/python3.6/dist-packages/redis/connection.py", line 538, in send_packed_command
    self.connect()
  File "/usr/local/lib/python3.6/dist-packages/redis/connection.py", line 442, in connect
    raise ConnectionError(self._error_message(e))
redis.exceptions.ConnectionError: Error 111 connecting to localhost:6379. Connection refused.

During handling of the above exception, another exception occurred:

Traceback (most recent call last):
  File "/usr/local/lib/python3.6/dist-packages/redis/connection.py", line 439, in connect
    sock = self._connect()
  File "/usr/local/lib/python3.6/dist-packages/redis/connection.py", line 494, in _connect
    raise err
  File "/usr/local/lib/python3.6/dist-packages/redis/connection.py", line 482, in _connect
    sock.connect(socket_address)
ConnectionRefusedError: [Errno 111] Connection refused

During handling of the above exception, another exception occurred:

Traceback (most recent call last):
  File "/usr/local/lib/python3.6/dist-packages/twisted/internet/defer.py", line 1418, in _inlineCallbacks
    result = g.send(result)
  File "/usr/local/lib/python3.6/dist-packages/scrapy/core/downloader/middleware.py", line 38, in process_request
    response = yield method(request=request, spider=spider)
  File "/home/jiangjin/桌面/xxoovideo/xxoovideo/middlewares.py", line 17, in process_request
    if self.bf.isContains(request.url):
  File "/home/jiangjin/桌面/xxoovideo/xxoovideo/tool/bloomfulter.py", line 50, in isContains
    ret = ret & self.server.getbit(name, loc)
  File "/usr/local/lib/python3.6/dist-packages/redis/client.py", line 894, in getbit
    return self.execute_command('GETBIT', name, offset)
  File "/usr/local/lib/python3.6/dist-packages/redis/client.py", line 578, in execute_command
    connection.send_command(*args)
  File "/usr/local/lib/python3.6/dist-packages/redis/connection.py", line 563, in send_command
    self.send_packed_command(self.pack_command(*args))
  File "/usr/local/lib/python3.6/dist-packages/redis/connection.py", line 538, in send_packed_command
    self.connect()
  File "/usr/local/lib/python3.6/dist-packages/redis/connection.py", line 442, in connect
    raise ConnectionError(self._error_message(e))
redis.exceptions.ConnectionError: Error 111 connecting to localhost:6379. Connection refused.
2020-02-08 23:35:36 [scrapy.core.scraper] ERROR: Error downloading <GET http://yj1.ceea3a8ea1f.pw/pw/html_data/111/2002/4598573.html>
Traceback (most recent call last):
  File "/usr/local/lib/python3.6/dist-packages/redis/connection.py", line 439, in connect
    sock = self._connect()
  File "/usr/local/lib/python3.6/dist-packages/redis/connection.py", line 494, in _connect
    raise err
  File "/usr/local/lib/python3.6/dist-packages/redis/connection.py", line 482, in _connect
    sock.connect(socket_address)
ConnectionRefusedError: [Errno 111] Connection refused

During handling of the above exception, another exception occurred:

Traceback (most recent call last):
  File "/usr/local/lib/python3.6/dist-packages/redis/client.py", line 572, in execute_command
    connection.send_command(*args)
  File "/usr/local/lib/python3.6/dist-packages/redis/connection.py", line 563, in send_command
    self.send_packed_command(self.pack_command(*args))
  File "/usr/local/lib/python3.6/dist-packages/redis/connection.py", line 538, in send_packed_command
    self.connect()
  File "/usr/local/lib/python3.6/dist-packages/redis/connection.py", line 442, in connect
    raise ConnectionError(self._error_message(e))
redis.exceptions.ConnectionError: Error 111 connecting to localhost:6379. Connection refused.

During handling of the above exception, another exception occurred:

Traceback (most recent call last):
  File "/usr/local/lib/python3.6/dist-packages/redis/connection.py", line 439, in connect
    sock = self._connect()
  File "/usr/local/lib/python3.6/dist-packages/redis/connection.py", line 494, in _connect
    raise err
  File "/usr/local/lib/python3.6/dist-packages/redis/connection.py", line 482, in _connect
    sock.connect(socket_address)
ConnectionRefusedError: [Errno 111] Connection refused

During handling of the above exception, another exception occurred:

Traceback (most recent call last):
  File "/usr/local/lib/python3.6/dist-packages/twisted/internet/defer.py", line 1418, in _inlineCallbacks
    result = g.send(result)
  File "/usr/local/lib/python3.6/dist-packages/scrapy/core/downloader/middleware.py", line 38, in process_request
    response = yield method(request=request, spider=spider)
  File "/home/jiangjin/桌面/xxoovideo/xxoovideo/middlewares.py", line 17, in process_request
    if self.bf.isContains(request.url):
  File "/home/jiangjin/桌面/xxoovideo/xxoovideo/tool/bloomfulter.py", line 50, in isContains
    ret = ret & self.server.getbit(name, loc)
  File "/usr/local/lib/python3.6/dist-packages/redis/client.py", line 894, in getbit
    return self.execute_command('GETBIT', name, offset)
  File "/usr/local/lib/python3.6/dist-packages/redis/client.py", line 578, in execute_command
    connection.send_command(*args)
  File "/usr/local/lib/python3.6/dist-packages/redis/connection.py", line 563, in send_command
    self.send_packed_command(self.pack_command(*args))
  File "/usr/local/lib/python3.6/dist-packages/redis/connection.py", line 538, in send_packed_command
    self.connect()
  File "/usr/local/lib/python3.6/dist-packages/redis/connection.py", line 442, in connect
    raise ConnectionError(self._error_message(e))
redis.exceptions.ConnectionError: Error 111 connecting to localhost:6379. Connection refused.
2020-02-08 23:35:36 [scrapy.core.scraper] ERROR: Error downloading <GET http://yj1.ceea3a8ea1f.pw/pw/html_data/111/2002/4598606.html>
Traceback (most recent call last):
  File "/usr/local/lib/python3.6/dist-packages/redis/connection.py", line 439, in connect
    sock = self._connect()
  File "/usr/local/lib/python3.6/dist-packages/redis/connection.py", line 494, in _connect
    raise err
  File "/usr/local/lib/python3.6/dist-packages/redis/connection.py", line 482, in _connect
    sock.connect(socket_address)
ConnectionRefusedError: [Errno 111] Connection refused

During handling of the above exception, another exception occurred:

Traceback (most recent call last):
  File "/usr/local/lib/python3.6/dist-packages/redis/client.py", line 572, in execute_command
    connection.send_command(*args)
  File "/usr/local/lib/python3.6/dist-packages/redis/connection.py", line 563, in send_command
    self.send_packed_command(self.pack_command(*args))
  File "/usr/local/lib/python3.6/dist-packages/redis/connection.py", line 538, in send_packed_command
    self.connect()
  File "/usr/local/lib/python3.6/dist-packages/redis/connection.py", line 442, in connect
    raise ConnectionError(self._error_message(e))
redis.exceptions.ConnectionError: Error 111 connecting to localhost:6379. Connection refused.

During handling of the above exception, another exception occurred:

Traceback (most recent call last):
  File "/usr/local/lib/python3.6/dist-packages/redis/connection.py", line 439, in connect
    sock = self._connect()
  File "/usr/local/lib/python3.6/dist-packages/redis/connection.py", line 494, in _connect
    raise err
  File "/usr/local/lib/python3.6/dist-packages/redis/connection.py", line 482, in _connect
    sock.connect(socket_address)
ConnectionRefusedError: [Errno 111] Connection refused

During handling of the above exception, another exception occurred:

Traceback (most recent call last):
  File "/usr/local/lib/python3.6/dist-packages/twisted/internet/defer.py", line 1418, in _inlineCallbacks
    result = g.send(result)
  File "/usr/local/lib/python3.6/dist-packages/scrapy/core/downloader/middleware.py", line 38, in process_request
    response = yield method(request=request, spider=spider)
  File "/home/jiangjin/桌面/xxoovideo/xxoovideo/middlewares.py", line 17, in process_request
    if self.bf.isContains(request.url):
  File "/home/jiangjin/桌面/xxoovideo/xxoovideo/tool/bloomfulter.py", line 50, in isContains
    ret = ret & self.server.getbit(name, loc)
  File "/usr/local/lib/python3.6/dist-packages/redis/client.py", line 894, in getbit
    return self.execute_command('GETBIT', name, offset)
  File "/usr/local/lib/python3.6/dist-packages/redis/client.py", line 578, in execute_command
    connection.send_command(*args)
  File "/usr/local/lib/python3.6/dist-packages/redis/connection.py", line 563, in send_command
    self.send_packed_command(self.pack_command(*args))
  File "/usr/local/lib/python3.6/dist-packages/redis/connection.py", line 538, in send_packed_command
    self.connect()
  File "/usr/local/lib/python3.6/dist-packages/redis/connection.py", line 442, in connect
    raise ConnectionError(self._error_message(e))
redis.exceptions.ConnectionError: Error 111 connecting to localhost:6379. Connection refused.
2020-02-08 23:35:36 [scrapy.core.scraper] ERROR: Error downloading <GET http://yj1.ceea3a8ea1f.pw/pw/html_data/111/2002/4598607.html>
Traceback (most recent call last):
  File "/usr/local/lib/python3.6/dist-packages/redis/connection.py", line 439, in connect
    sock = self._connect()
  File "/usr/local/lib/python3.6/dist-packages/redis/connection.py", line 494, in _connect
    raise err
  File "/usr/local/lib/python3.6/dist-packages/redis/connection.py", line 482, in _connect
    sock.connect(socket_address)
ConnectionRefusedError: [Errno 111] Connection refused

During handling of the above exception, another exception occurred:

Traceback (most recent call last):
  File "/usr/local/lib/python3.6/dist-packages/redis/client.py", line 572, in execute_command
    connection.send_command(*args)
  File "/usr/local/lib/python3.6/dist-packages/redis/connection.py", line 563, in send_command
    self.send_packed_command(self.pack_command(*args))
  File "/usr/local/lib/python3.6/dist-packages/redis/connection.py", line 538, in send_packed_command
    self.connect()
  File "/usr/local/lib/python3.6/dist-packages/redis/connection.py", line 442, in connect
    raise ConnectionError(self._error_message(e))
redis.exceptions.ConnectionError: Error 111 connecting to localhost:6379. Connection refused.

During handling of the above exception, another exception occurred:

Traceback (most recent call last):
  File "/usr/local/lib/python3.6/dist-packages/redis/connection.py", line 439, in connect
    sock = self._connect()
  File "/usr/local/lib/python3.6/dist-packages/redis/connection.py", line 494, in _connect
    raise err
  File "/usr/local/lib/python3.6/dist-packages/redis/connection.py", line 482, in _connect
    sock.connect(socket_address)
ConnectionRefusedError: [Errno 111] Connection refused

During handling of the above exception, another exception occurred:

Traceback (most recent call last):
  File "/usr/local/lib/python3.6/dist-packages/twisted/internet/defer.py", line 1418, in _inlineCallbacks
    result = g.send(result)
  File "/usr/local/lib/python3.6/dist-packages/scrapy/core/downloader/middleware.py", line 38, in process_request
    response = yield method(request=request, spider=spider)
  File "/home/jiangjin/桌面/xxoovideo/xxoovideo/middlewares.py", line 17, in process_request
    if self.bf.isContains(request.url):
  File "/home/jiangjin/桌面/xxoovideo/xxoovideo/tool/bloomfulter.py", line 50, in isContains
    ret = ret & self.server.getbit(name, loc)
  File "/usr/local/lib/python3.6/dist-packages/redis/client.py", line 894, in getbit
    return self.execute_command('GETBIT', name, offset)
  File "/usr/local/lib/python3.6/dist-packages/redis/client.py", line 578, in execute_command
    connection.send_command(*args)
  File "/usr/local/lib/python3.6/dist-packages/redis/connection.py", line 563, in send_command
    self.send_packed_command(self.pack_command(*args))
  File "/usr/local/lib/python3.6/dist-packages/redis/connection.py", line 538, in send_packed_command
    self.connect()
  File "/usr/local/lib/python3.6/dist-packages/redis/connection.py", line 442, in connect
    raise ConnectionError(self._error_message(e))
redis.exceptions.ConnectionError: Error 111 connecting to localhost:6379. Connection refused.
2020-02-08 23:35:36 [scrapy.core.scraper] ERROR: Error downloading <GET http://yj1.ceea3a8ea1f.pw/pw/html_data/111/2002/4598610.html>
Traceback (most recent call last):
  File "/usr/local/lib/python3.6/dist-packages/redis/connection.py", line 439, in connect
    sock = self._connect()
  File "/usr/local/lib/python3.6/dist-packages/redis/connection.py", line 494, in _connect
    raise err
  File "/usr/local/lib/python3.6/dist-packages/redis/connection.py", line 482, in _connect
    sock.connect(socket_address)
ConnectionRefusedError: [Errno 111] Connection refused

During handling of the above exception, another exception occurred:

Traceback (most recent call last):
  File "/usr/local/lib/python3.6/dist-packages/redis/client.py", line 572, in execute_command
    connection.send_command(*args)
  File "/usr/local/lib/python3.6/dist-packages/redis/connection.py", line 563, in send_command
    self.send_packed_command(self.pack_command(*args))
  File "/usr/local/lib/python3.6/dist-packages/redis/connection.py", line 538, in send_packed_command
    self.connect()
  File "/usr/local/lib/python3.6/dist-packages/redis/connection.py", line 442, in connect
    raise ConnectionError(self._error_message(e))
redis.exceptions.ConnectionError: Error 111 connecting to localhost:6379. Connection refused.

During handling of the above exception, another exception occurred:

Traceback (most recent call last):
  File "/usr/local/lib/python3.6/dist-packages/redis/connection.py", line 439, in connect
    sock = self._connect()
  File "/usr/local/lib/python3.6/dist-packages/redis/connection.py", line 494, in _connect
    raise err
  File "/usr/local/lib/python3.6/dist-packages/redis/connection.py", line 482, in _connect
    sock.connect(socket_address)
ConnectionRefusedError: [Errno 111] Connection refused

During handling of the above exception, another exception occurred:

Traceback (most recent call last):
  File "/usr/local/lib/python3.6/dist-packages/twisted/internet/defer.py", line 1418, in _inlineCallbacks
    result = g.send(result)
  File "/usr/local/lib/python3.6/dist-packages/scrapy/core/downloader/middleware.py", line 38, in process_request
    response = yield method(request=request, spider=spider)
  File "/home/jiangjin/桌面/xxoovideo/xxoovideo/middlewares.py", line 17, in process_request
    if self.bf.isContains(request.url):
  File "/home/jiangjin/桌面/xxoovideo/xxoovideo/tool/bloomfulter.py", line 50, in isContains
    ret = ret & self.server.getbit(name, loc)
  File "/usr/local/lib/python3.6/dist-packages/redis/client.py", line 894, in getbit
    return self.execute_command('GETBIT', name, offset)
  File "/usr/local/lib/python3.6/dist-packages/redis/client.py", line 578, in execute_command
    connection.send_command(*args)
  File "/usr/local/lib/python3.6/dist-packages/redis/connection.py", line 563, in send_command
    self.send_packed_command(self.pack_command(*args))
  File "/usr/local/lib/python3.6/dist-packages/redis/connection.py", line 538, in send_packed_command
    self.connect()
  File "/usr/local/lib/python3.6/dist-packages/redis/connection.py", line 442, in connect
    raise ConnectionError(self._error_message(e))
redis.exceptions.ConnectionError: Error 111 connecting to localhost:6379. Connection refused.
2020-02-08 23:35:36 [scrapy.core.scraper] ERROR: Error downloading <GET http://yj1.ceea3a8ea1f.pw/pw/html_data/111/2002/4598612.html>
Traceback (most recent call last):
  File "/usr/local/lib/python3.6/dist-packages/redis/connection.py", line 439, in connect
    sock = self._connect()
  File "/usr/local/lib/python3.6/dist-packages/redis/connection.py", line 494, in _connect
    raise err
  File "/usr/local/lib/python3.6/dist-packages/redis/connection.py", line 482, in _connect
    sock.connect(socket_address)
ConnectionRefusedError: [Errno 111] Connection refused

During handling of the above exception, another exception occurred:

Traceback (most recent call last):
  File "/usr/local/lib/python3.6/dist-packages/redis/client.py", line 572, in execute_command
    connection.send_command(*args)
  File "/usr/local/lib/python3.6/dist-packages/redis/connection.py", line 563, in send_command
    self.send_packed_command(self.pack_command(*args))
  File "/usr/local/lib/python3.6/dist-packages/redis/connection.py", line 538, in send_packed_command
    self.connect()
  File "/usr/local/lib/python3.6/dist-packages/redis/connection.py", line 442, in connect
    raise ConnectionError(self._error_message(e))
redis.exceptions.ConnectionError: Error 111 connecting to localhost:6379. Connection refused.

During handling of the above exception, another exception occurred:

Traceback (most recent call last):
  File "/usr/local/lib/python3.6/dist-packages/redis/connection.py", line 439, in connect
    sock = self._connect()
  File "/usr/local/lib/python3.6/dist-packages/redis/connection.py", line 494, in _connect
    raise err
  File "/usr/local/lib/python3.6/dist-packages/redis/connection.py", line 482, in _connect
    sock.connect(socket_address)
ConnectionRefusedError: [Errno 111] Connection refused

During handling of the above exception, another exception occurred:

Traceback (most recent call last):
  File "/usr/local/lib/python3.6/dist-packages/twisted/internet/defer.py", line 1418, in _inlineCallbacks
    result = g.send(result)
  File "/usr/local/lib/python3.6/dist-packages/scrapy/core/downloader/middleware.py", line 38, in process_request
    response = yield method(request=request, spider=spider)
  File "/home/jiangjin/桌面/xxoovideo/xxoovideo/middlewares.py", line 17, in process_request
    if self.bf.isContains(request.url):
  File "/home/jiangjin/桌面/xxoovideo/xxoovideo/tool/bloomfulter.py", line 50, in isContains
    ret = ret & self.server.getbit(name, loc)
  File "/usr/local/lib/python3.6/dist-packages/redis/client.py", line 894, in getbit
    return self.execute_command('GETBIT', name, offset)
  File "/usr/local/lib/python3.6/dist-packages/redis/client.py", line 578, in execute_command
    connection.send_command(*args)
  File "/usr/local/lib/python3.6/dist-packages/redis/connection.py", line 563, in send_command
    self.send_packed_command(self.pack_command(*args))
  File "/usr/local/lib/python3.6/dist-packages/redis/connection.py", line 538, in send_packed_command
    self.connect()
  File "/usr/local/lib/python3.6/dist-packages/redis/connection.py", line 442, in connect
    raise ConnectionError(self._error_message(e))
redis.exceptions.ConnectionError: Error 111 connecting to localhost:6379. Connection refused.
2020-02-08 23:35:36 [scrapy.core.scraper] ERROR: Error downloading <GET http://yj1.ceea3a8ea1f.pw/pw/html_data/111/2002/4598615.html>
Traceback (most recent call last):
  File "/usr/local/lib/python3.6/dist-packages/redis/connection.py", line 439, in connect
    sock = self._connect()
  File "/usr/local/lib/python3.6/dist-packages/redis/connection.py", line 494, in _connect
    raise err
  File "/usr/local/lib/python3.6/dist-packages/redis/connection.py", line 482, in _connect
    sock.connect(socket_address)
ConnectionRefusedError: [Errno 111] Connection refused

During handling of the above exception, another exception occurred:

Traceback (most recent call last):
  File "/usr/local/lib/python3.6/dist-packages/redis/client.py", line 572, in execute_command
    connection.send_command(*args)
  File "/usr/local/lib/python3.6/dist-packages/redis/connection.py", line 563, in send_command
    self.send_packed_command(self.pack_command(*args))
  File "/usr/local/lib/python3.6/dist-packages/redis/connection.py", line 538, in send_packed_command
    self.connect()
  File "/usr/local/lib/python3.6/dist-packages/redis/connection.py", line 442, in connect
    raise ConnectionError(self._error_message(e))
redis.exceptions.ConnectionError: Error 111 connecting to localhost:6379. Connection refused.

During handling of the above exception, another exception occurred:

Traceback (most recent call last):
  File "/usr/local/lib/python3.6/dist-packages/redis/connection.py", line 439, in connect
    sock = self._connect()
  File "/usr/local/lib/python3.6/dist-packages/redis/connection.py", line 494, in _connect
    raise err
  File "/usr/local/lib/python3.6/dist-packages/redis/connection.py", line 482, in _connect
    sock.connect(socket_address)
ConnectionRefusedError: [Errno 111] Connection refused

During handling of the above exception, another exception occurred:

Traceback (most recent call last):
  File "/usr/local/lib/python3.6/dist-packages/twisted/internet/defer.py", line 1418, in _inlineCallbacks
    result = g.send(result)
  File "/usr/local/lib/python3.6/dist-packages/scrapy/core/downloader/middleware.py", line 38, in process_request
    response = yield method(request=request, spider=spider)
  File "/home/jiangjin/桌面/xxoovideo/xxoovideo/middlewares.py", line 17, in process_request
    if self.bf.isContains(request.url):
  File "/home/jiangjin/桌面/xxoovideo/xxoovideo/tool/bloomfulter.py", line 50, in isContains
    ret = ret & self.server.getbit(name, loc)
  File "/usr/local/lib/python3.6/dist-packages/redis/client.py", line 894, in getbit
    return self.execute_command('GETBIT', name, offset)
  File "/usr/local/lib/python3.6/dist-packages/redis/client.py", line 578, in execute_command
    connection.send_command(*args)
  File "/usr/local/lib/python3.6/dist-packages/redis/connection.py", line 563, in send_command
    self.send_packed_command(self.pack_command(*args))
  File "/usr/local/lib/python3.6/dist-packages/redis/connection.py", line 538, in send_packed_command
    self.connect()
  File "/usr/local/lib/python3.6/dist-packages/redis/connection.py", line 442, in connect
    raise ConnectionError(self._error_message(e))
redis.exceptions.ConnectionError: Error 111 connecting to localhost:6379. Connection refused.
2020-02-08 23:35:36 [scrapy.core.scraper] ERROR: Error downloading <GET http://yj1.ceea3a8ea1f.pw/pw/html_data/111/2002/4598618.html>
Traceback (most recent call last):
  File "/usr/local/lib/python3.6/dist-packages/redis/connection.py", line 439, in connect
    sock = self._connect()
  File "/usr/local/lib/python3.6/dist-packages/redis/connection.py", line 494, in _connect
    raise err
  File "/usr/local/lib/python3.6/dist-packages/redis/connection.py", line 482, in _connect
    sock.connect(socket_address)
ConnectionRefusedError: [Errno 111] Connection refused

During handling of the above exception, another exception occurred:

Traceback (most recent call last):
  File "/usr/local/lib/python3.6/dist-packages/redis/client.py", line 572, in execute_command
    connection.send_command(*args)
  File "/usr/local/lib/python3.6/dist-packages/redis/connection.py", line 563, in send_command
    self.send_packed_command(self.pack_command(*args))
  File "/usr/local/lib/python3.6/dist-packages/redis/connection.py", line 538, in send_packed_command
    self.connect()
  File "/usr/local/lib/python3.6/dist-packages/redis/connection.py", line 442, in connect
    raise ConnectionError(self._error_message(e))
redis.exceptions.ConnectionError: Error 111 connecting to localhost:6379. Connection refused.

During handling of the above exception, another exception occurred:

Traceback (most recent call last):
  File "/usr/local/lib/python3.6/dist-packages/redis/connection.py", line 439, in connect
    sock = self._connect()
  File "/usr/local/lib/python3.6/dist-packages/redis/connection.py", line 494, in _connect
    raise err
  File "/usr/local/lib/python3.6/dist-packages/redis/connection.py", line 482, in _connect
    sock.connect(socket_address)
ConnectionRefusedError: [Errno 111] Connection refused

During handling of the above exception, another exception occurred:

Traceback (most recent call last):
  File "/usr/local/lib/python3.6/dist-packages/twisted/internet/defer.py", line 1418, in _inlineCallbacks
    result = g.send(result)
  File "/usr/local/lib/python3.6/dist-packages/scrapy/core/downloader/middleware.py", line 38, in process_request
    response = yield method(request=request, spider=spider)
  File "/home/jiangjin/桌面/xxoovideo/xxoovideo/middlewares.py", line 17, in process_request
    if self.bf.isContains(request.url):
  File "/home/jiangjin/桌面/xxoovideo/xxoovideo/tool/bloomfulter.py", line 50, in isContains
    ret = ret & self.server.getbit(name, loc)
  File "/usr/local/lib/python3.6/dist-packages/redis/client.py", line 894, in getbit
    return self.execute_command('GETBIT', name, offset)
  File "/usr/local/lib/python3.6/dist-packages/redis/client.py", line 578, in execute_command
    connection.send_command(*args)
  File "/usr/local/lib/python3.6/dist-packages/redis/connection.py", line 563, in send_command
    self.send_packed_command(self.pack_command(*args))
  File "/usr/local/lib/python3.6/dist-packages/redis/connection.py", line 538, in send_packed_command
    self.connect()
  File "/usr/local/lib/python3.6/dist-packages/redis/connection.py", line 442, in connect
    raise ConnectionError(self._error_message(e))
redis.exceptions.ConnectionError: Error 111 connecting to localhost:6379. Connection refused.
2020-02-08 23:35:36 [scrapy.core.scraper] ERROR: Error downloading <GET http://yj1.ceea3a8ea1f.pw/pw/html_data/111/2002/4598622.html>
Traceback (most recent call last):
  File "/usr/local/lib/python3.6/dist-packages/redis/connection.py", line 439, in connect
    sock = self._connect()
  File "/usr/local/lib/python3.6/dist-packages/redis/connection.py", line 494, in _connect
    raise err
  File "/usr/local/lib/python3.6/dist-packages/redis/connection.py", line 482, in _connect
    sock.connect(socket_address)
ConnectionRefusedError: [Errno 111] Connection refused

During handling of the above exception, another exception occurred:

Traceback (most recent call last):
  File "/usr/local/lib/python3.6/dist-packages/redis/client.py", line 572, in execute_command
    connection.send_command(*args)
  File "/usr/local/lib/python3.6/dist-packages/redis/connection.py", line 563, in send_command
    self.send_packed_command(self.pack_command(*args))
  File "/usr/local/lib/python3.6/dist-packages/redis/connection.py", line 538, in send_packed_command
    self.connect()
  File "/usr/local/lib/python3.6/dist-packages/redis/connection.py", line 442, in connect
    raise ConnectionError(self._error_message(e))
redis.exceptions.ConnectionError: Error 111 connecting to localhost:6379. Connection refused.

During handling of the above exception, another exception occurred:

Traceback (most recent call last):
  File "/usr/local/lib/python3.6/dist-packages/redis/connection.py", line 439, in connect
    sock = self._connect()
  File "/usr/local/lib/python3.6/dist-packages/redis/connection.py", line 494, in _connect
    raise err
  File "/usr/local/lib/python3.6/dist-packages/redis/connection.py", line 482, in _connect
    sock.connect(socket_address)
ConnectionRefusedError: [Errno 111] Connection refused

During handling of the above exception, another exception occurred:

Traceback (most recent call last):
  File "/usr/local/lib/python3.6/dist-packages/twisted/internet/defer.py", line 1418, in _inlineCallbacks
    result = g.send(result)
  File "/usr/local/lib/python3.6/dist-packages/scrapy/core/downloader/middleware.py", line 38, in process_request
    response = yield method(request=request, spider=spider)
  File "/home/jiangjin/桌面/xxoovideo/xxoovideo/middlewares.py", line 17, in process_request
    if self.bf.isContains(request.url):
  File "/home/jiangjin/桌面/xxoovideo/xxoovideo/tool/bloomfulter.py", line 50, in isContains
    ret = ret & self.server.getbit(name, loc)
  File "/usr/local/lib/python3.6/dist-packages/redis/client.py", line 894, in getbit
    return self.execute_command('GETBIT', name, offset)
  File "/usr/local/lib/python3.6/dist-packages/redis/client.py", line 578, in execute_command
    connection.send_command(*args)
  File "/usr/local/lib/python3.6/dist-packages/redis/connection.py", line 563, in send_command
    self.send_packed_command(self.pack_command(*args))
  File "/usr/local/lib/python3.6/dist-packages/redis/connection.py", line 538, in send_packed_command
    self.connect()
  File "/usr/local/lib/python3.6/dist-packages/redis/connection.py", line 442, in connect
    raise ConnectionError(self._error_message(e))
redis.exceptions.ConnectionError: Error 111 connecting to localhost:6379. Connection refused.
2020-02-08 23:35:36 [scrapy.core.scraper] ERROR: Error downloading <GET http://yj1.ceea3a8ea1f.pw/pw/html_data/111/2002/4598623.html>
Traceback (most recent call last):
  File "/usr/local/lib/python3.6/dist-packages/redis/connection.py", line 439, in connect
    sock = self._connect()
  File "/usr/local/lib/python3.6/dist-packages/redis/connection.py", line 494, in _connect
    raise err
  File "/usr/local/lib/python3.6/dist-packages/redis/connection.py", line 482, in _connect
    sock.connect(socket_address)
ConnectionRefusedError: [Errno 111] Connection refused

During handling of the above exception, another exception occurred:

Traceback (most recent call last):
  File "/usr/local/lib/python3.6/dist-packages/redis/client.py", line 572, in execute_command
    connection.send_command(*args)
  File "/usr/local/lib/python3.6/dist-packages/redis/connection.py", line 563, in send_command
    self.send_packed_command(self.pack_command(*args))
  File "/usr/local/lib/python3.6/dist-packages/redis/connection.py", line 538, in send_packed_command
    self.connect()
  File "/usr/local/lib/python3.6/dist-packages/redis/connection.py", line 442, in connect
    raise ConnectionError(self._error_message(e))
redis.exceptions.ConnectionError: Error 111 connecting to localhost:6379. Connection refused.

During handling of the above exception, another exception occurred:

Traceback (most recent call last):
  File "/usr/local/lib/python3.6/dist-packages/redis/connection.py", line 439, in connect
    sock = self._connect()
  File "/usr/local/lib/python3.6/dist-packages/redis/connection.py", line 494, in _connect
    raise err
  File "/usr/local/lib/python3.6/dist-packages/redis/connection.py", line 482, in _connect
    sock.connect(socket_address)
ConnectionRefusedError: [Errno 111] Connection refused

During handling of the above exception, another exception occurred:

Traceback (most recent call last):
  File "/usr/local/lib/python3.6/dist-packages/twisted/internet/defer.py", line 1418, in _inlineCallbacks
    result = g.send(result)
  File "/usr/local/lib/python3.6/dist-packages/scrapy/core/downloader/middleware.py", line 38, in process_request
    response = yield method(request=request, spider=spider)
  File "/home/jiangjin/桌面/xxoovideo/xxoovideo/middlewares.py", line 17, in process_request
    if self.bf.isContains(request.url):
  File "/home/jiangjin/桌面/xxoovideo/xxoovideo/tool/bloomfulter.py", line 50, in isContains
    ret = ret & self.server.getbit(name, loc)
  File "/usr/local/lib/python3.6/dist-packages/redis/client.py", line 894, in getbit
    return self.execute_command('GETBIT', name, offset)
  File "/usr/local/lib/python3.6/dist-packages/redis/client.py", line 578, in execute_command
    connection.send_command(*args)
  File "/usr/local/lib/python3.6/dist-packages/redis/connection.py", line 563, in send_command
    self.send_packed_command(self.pack_command(*args))
  File "/usr/local/lib/python3.6/dist-packages/redis/connection.py", line 538, in send_packed_command
    self.connect()
  File "/usr/local/lib/python3.6/dist-packages/redis/connection.py", line 442, in connect
    raise ConnectionError(self._error_message(e))
redis.exceptions.ConnectionError: Error 111 connecting to localhost:6379. Connection refused.
2020-02-08 23:35:36 [scrapy.core.scraper] ERROR: Error downloading <GET http://yj1.ceea3a8ea1f.pw/pw/html_data/111/2002/4598624.html>
Traceback (most recent call last):
  File "/usr/local/lib/python3.6/dist-packages/redis/connection.py", line 439, in connect
    sock = self._connect()
  File "/usr/local/lib/python3.6/dist-packages/redis/connection.py", line 494, in _connect
    raise err
  File "/usr/local/lib/python3.6/dist-packages/redis/connection.py", line 482, in _connect
    sock.connect(socket_address)
ConnectionRefusedError: [Errno 111] Connection refused

During handling of the above exception, another exception occurred:

Traceback (most recent call last):
  File "/usr/local/lib/python3.6/dist-packages/redis/client.py", line 572, in execute_command
    connection.send_command(*args)
  File "/usr/local/lib/python3.6/dist-packages/redis/connection.py", line 563, in send_command
    self.send_packed_command(self.pack_command(*args))
  File "/usr/local/lib/python3.6/dist-packages/redis/connection.py", line 538, in send_packed_command
    self.connect()
  File "/usr/local/lib/python3.6/dist-packages/redis/connection.py", line 442, in connect
    raise ConnectionError(self._error_message(e))
redis.exceptions.ConnectionError: Error 111 connecting to localhost:6379. Connection refused.

During handling of the above exception, another exception occurred:

Traceback (most recent call last):
  File "/usr/local/lib/python3.6/dist-packages/redis/connection.py", line 439, in connect
    sock = self._connect()
  File "/usr/local/lib/python3.6/dist-packages/redis/connection.py", line 494, in _connect
    raise err
  File "/usr/local/lib/python3.6/dist-packages/redis/connection.py", line 482, in _connect
    sock.connect(socket_address)
ConnectionRefusedError: [Errno 111] Connection refused

During handling of the above exception, another exception occurred:

Traceback (most recent call last):
  File "/usr/local/lib/python3.6/dist-packages/twisted/internet/defer.py", line 1418, in _inlineCallbacks
    result = g.send(result)
  File "/usr/local/lib/python3.6/dist-packages/scrapy/core/downloader/middleware.py", line 38, in process_request
    response = yield method(request=request, spider=spider)
  File "/home/jiangjin/桌面/xxoovideo/xxoovideo/middlewares.py", line 17, in process_request
    if self.bf.isContains(request.url):
  File "/home/jiangjin/桌面/xxoovideo/xxoovideo/tool/bloomfulter.py", line 50, in isContains
    ret = ret & self.server.getbit(name, loc)
  File "/usr/local/lib/python3.6/dist-packages/redis/client.py", line 894, in getbit
    return self.execute_command('GETBIT', name, offset)
  File "/usr/local/lib/python3.6/dist-packages/redis/client.py", line 578, in execute_command
    connection.send_command(*args)
  File "/usr/local/lib/python3.6/dist-packages/redis/connection.py", line 563, in send_command
    self.send_packed_command(self.pack_command(*args))
  File "/usr/local/lib/python3.6/dist-packages/redis/connection.py", line 538, in send_packed_command
    self.connect()
  File "/usr/local/lib/python3.6/dist-packages/redis/connection.py", line 442, in connect
    raise ConnectionError(self._error_message(e))
redis.exceptions.ConnectionError: Error 111 connecting to localhost:6379. Connection refused.
2020-02-08 23:35:36 [scrapy.core.scraper] ERROR: Error downloading <GET http://yj1.ceea3a8ea1f.pw/pw/html_data/111/2002/4598625.html>
Traceback (most recent call last):
  File "/usr/local/lib/python3.6/dist-packages/redis/connection.py", line 439, in connect
    sock = self._connect()
  File "/usr/local/lib/python3.6/dist-packages/redis/connection.py", line 494, in _connect
    raise err
  File "/usr/local/lib/python3.6/dist-packages/redis/connection.py", line 482, in _connect
    sock.connect(socket_address)
ConnectionRefusedError: [Errno 111] Connection refused

During handling of the above exception, another exception occurred:

Traceback (most recent call last):
  File "/usr/local/lib/python3.6/dist-packages/redis/client.py", line 572, in execute_command
    connection.send_command(*args)
  File "/usr/local/lib/python3.6/dist-packages/redis/connection.py", line 563, in send_command
    self.send_packed_command(self.pack_command(*args))
  File "/usr/local/lib/python3.6/dist-packages/redis/connection.py", line 538, in send_packed_command
    self.connect()
  File "/usr/local/lib/python3.6/dist-packages/redis/connection.py", line 442, in connect
    raise ConnectionError(self._error_message(e))
redis.exceptions.ConnectionError: Error 111 connecting to localhost:6379. Connection refused.

During handling of the above exception, another exception occurred:

Traceback (most recent call last):
  File "/usr/local/lib/python3.6/dist-packages/redis/connection.py", line 439, in connect
    sock = self._connect()
  File "/usr/local/lib/python3.6/dist-packages/redis/connection.py", line 494, in _connect
    raise err
  File "/usr/local/lib/python3.6/dist-packages/redis/connection.py", line 482, in _connect
    sock.connect(socket_address)
ConnectionRefusedError: [Errno 111] Connection refused

During handling of the above exception, another exception occurred:

Traceback (most recent call last):
  File "/usr/local/lib/python3.6/dist-packages/twisted/internet/defer.py", line 1418, in _inlineCallbacks
    result = g.send(result)
  File "/usr/local/lib/python3.6/dist-packages/scrapy/core/downloader/middleware.py", line 38, in process_request
    response = yield method(request=request, spider=spider)
  File "/home/jiangjin/桌面/xxoovideo/xxoovideo/middlewares.py", line 17, in process_request
    if self.bf.isContains(request.url):
  File "/home/jiangjin/桌面/xxoovideo/xxoovideo/tool/bloomfulter.py", line 50, in isContains
    ret = ret & self.server.getbit(name, loc)
  File "/usr/local/lib/python3.6/dist-packages/redis/client.py", line 894, in getbit
    return self.execute_command('GETBIT', name, offset)
  File "/usr/local/lib/python3.6/dist-packages/redis/client.py", line 578, in execute_command
    connection.send_command(*args)
  File "/usr/local/lib/python3.6/dist-packages/redis/connection.py", line 563, in send_command
    self.send_packed_command(self.pack_command(*args))
  File "/usr/local/lib/python3.6/dist-packages/redis/connection.py", line 538, in send_packed_command
    self.connect()
  File "/usr/local/lib/python3.6/dist-packages/redis/connection.py", line 442, in connect
    raise ConnectionError(self._error_message(e))
redis.exceptions.ConnectionError: Error 111 connecting to localhost:6379. Connection refused.
2020-02-08 23:35:36 [scrapy.core.scraper] ERROR: Error downloading <GET http://yj1.ceea3a8ea1f.pw/pw/html_data/111/2002/4598626.html>
Traceback (most recent call last):
  File "/usr/local/lib/python3.6/dist-packages/redis/connection.py", line 439, in connect
    sock = self._connect()
  File "/usr/local/lib/python3.6/dist-packages/redis/connection.py", line 494, in _connect
    raise err
  File "/usr/local/lib/python3.6/dist-packages/redis/connection.py", line 482, in _connect
    sock.connect(socket_address)
ConnectionRefusedError: [Errno 111] Connection refused

During handling of the above exception, another exception occurred:

Traceback (most recent call last):
  File "/usr/local/lib/python3.6/dist-packages/redis/client.py", line 572, in execute_command
    connection.send_command(*args)
  File "/usr/local/lib/python3.6/dist-packages/redis/connection.py", line 563, in send_command
    self.send_packed_command(self.pack_command(*args))
  File "/usr/local/lib/python3.6/dist-packages/redis/connection.py", line 538, in send_packed_command
    self.connect()
  File "/usr/local/lib/python3.6/dist-packages/redis/connection.py", line 442, in connect
    raise ConnectionError(self._error_message(e))
redis.exceptions.ConnectionError: Error 111 connecting to localhost:6379. Connection refused.

During handling of the above exception, another exception occurred:

Traceback (most recent call last):
  File "/usr/local/lib/python3.6/dist-packages/redis/connection.py", line 439, in connect
    sock = self._connect()
  File "/usr/local/lib/python3.6/dist-packages/redis/connection.py", line 494, in _connect
    raise err
  File "/usr/local/lib/python3.6/dist-packages/redis/connection.py", line 482, in _connect
    sock.connect(socket_address)
ConnectionRefusedError: [Errno 111] Connection refused

During handling of the above exception, another exception occurred:

Traceback (most recent call last):
  File "/usr/local/lib/python3.6/dist-packages/twisted/internet/defer.py", line 1418, in _inlineCallbacks
    result = g.send(result)
  File "/usr/local/lib/python3.6/dist-packages/scrapy/core/downloader/middleware.py", line 38, in process_request
    response = yield method(request=request, spider=spider)
  File "/home/jiangjin/桌面/xxoovideo/xxoovideo/middlewares.py", line 17, in process_request
    if self.bf.isContains(request.url):
  File "/home/jiangjin/桌面/xxoovideo/xxoovideo/tool/bloomfulter.py", line 50, in isContains
    ret = ret & self.server.getbit(name, loc)
  File "/usr/local/lib/python3.6/dist-packages/redis/client.py", line 894, in getbit
    return self.execute_command('GETBIT', name, offset)
  File "/usr/local/lib/python3.6/dist-packages/redis/client.py", line 578, in execute_command
    connection.send_command(*args)
  File "/usr/local/lib/python3.6/dist-packages/redis/connection.py", line 563, in send_command
    self.send_packed_command(self.pack_command(*args))
  File "/usr/local/lib/python3.6/dist-packages/redis/connection.py", line 538, in send_packed_command
    self.connect()
  File "/usr/local/lib/python3.6/dist-packages/redis/connection.py", line 442, in connect
    raise ConnectionError(self._error_message(e))
redis.exceptions.ConnectionError: Error 111 connecting to localhost:6379. Connection refused.
2020-02-08 23:35:36 [scrapy.core.scraper] ERROR: Error downloading <GET http://yj1.ceea3a8ea1f.pw/pw/html_data/111/2002/4598627.html>
Traceback (most recent call last):
  File "/usr/local/lib/python3.6/dist-packages/redis/connection.py", line 439, in connect
    sock = self._connect()
  File "/usr/local/lib/python3.6/dist-packages/redis/connection.py", line 494, in _connect
    raise err
  File "/usr/local/lib/python3.6/dist-packages/redis/connection.py", line 482, in _connect
    sock.connect(socket_address)
ConnectionRefusedError: [Errno 111] Connection refused

During handling of the above exception, another exception occurred:

Traceback (most recent call last):
  File "/usr/local/lib/python3.6/dist-packages/redis/client.py", line 572, in execute_command
    connection.send_command(*args)
  File "/usr/local/lib/python3.6/dist-packages/redis/connection.py", line 563, in send_command
    self.send_packed_command(self.pack_command(*args))
  File "/usr/local/lib/python3.6/dist-packages/redis/connection.py", line 538, in send_packed_command
    self.connect()
  File "/usr/local/lib/python3.6/dist-packages/redis/connection.py", line 442, in connect
    raise ConnectionError(self._error_message(e))
redis.exceptions.ConnectionError: Error 111 connecting to localhost:6379. Connection refused.

During handling of the above exception, another exception occurred:

Traceback (most recent call last):
  File "/usr/local/lib/python3.6/dist-packages/redis/connection.py", line 439, in connect
    sock = self._connect()
  File "/usr/local/lib/python3.6/dist-packages/redis/connection.py", line 494, in _connect
    raise err
  File "/usr/local/lib/python3.6/dist-packages/redis/connection.py", line 482, in _connect
    sock.connect(socket_address)
ConnectionRefusedError: [Errno 111] Connection refused

During handling of the above exception, another exception occurred:

Traceback (most recent call last):
  File "/usr/local/lib/python3.6/dist-packages/twisted/internet/defer.py", line 1418, in _inlineCallbacks
    result = g.send(result)
  File "/usr/local/lib/python3.6/dist-packages/scrapy/core/downloader/middleware.py", line 38, in process_request
    response = yield method(request=request, spider=spider)
  File "/home/jiangjin/桌面/xxoovideo/xxoovideo/middlewares.py", line 17, in process_request
    if self.bf.isContains(request.url):
  File "/home/jiangjin/桌面/xxoovideo/xxoovideo/tool/bloomfulter.py", line 50, in isContains
    ret = ret & self.server.getbit(name, loc)
  File "/usr/local/lib/python3.6/dist-packages/redis/client.py", line 894, in getbit
    return self.execute_command('GETBIT', name, offset)
  File "/usr/local/lib/python3.6/dist-packages/redis/client.py", line 578, in execute_command
    connection.send_command(*args)
  File "/usr/local/lib/python3.6/dist-packages/redis/connection.py", line 563, in send_command
    self.send_packed_command(self.pack_command(*args))
  File "/usr/local/lib/python3.6/dist-packages/redis/connection.py", line 538, in send_packed_command
    self.connect()
  File "/usr/local/lib/python3.6/dist-packages/redis/connection.py", line 442, in connect
    raise ConnectionError(self._error_message(e))
redis.exceptions.ConnectionError: Error 111 connecting to localhost:6379. Connection refused.
2020-02-08 23:35:36 [scrapy.core.scraper] ERROR: Error downloading <GET http://yj1.ceea3a8ea1f.pw/pw/html_data/111/2002/4598628.html>
Traceback (most recent call last):
  File "/usr/local/lib/python3.6/dist-packages/redis/connection.py", line 439, in connect
    sock = self._connect()
  File "/usr/local/lib/python3.6/dist-packages/redis/connection.py", line 494, in _connect
    raise err
  File "/usr/local/lib/python3.6/dist-packages/redis/connection.py", line 482, in _connect
    sock.connect(socket_address)
ConnectionRefusedError: [Errno 111] Connection refused

During handling of the above exception, another exception occurred:

Traceback (most recent call last):
  File "/usr/local/lib/python3.6/dist-packages/redis/client.py", line 572, in execute_command
    connection.send_command(*args)
  File "/usr/local/lib/python3.6/dist-packages/redis/connection.py", line 563, in send_command
    self.send_packed_command(self.pack_command(*args))
  File "/usr/local/lib/python3.6/dist-packages/redis/connection.py", line 538, in send_packed_command
    self.connect()
  File "/usr/local/lib/python3.6/dist-packages/redis/connection.py", line 442, in connect
    raise ConnectionError(self._error_message(e))
redis.exceptions.ConnectionError: Error 111 connecting to localhost:6379. Connection refused.

During handling of the above exception, another exception occurred:

Traceback (most recent call last):
  File "/usr/local/lib/python3.6/dist-packages/redis/connection.py", line 439, in connect
    sock = self._connect()
  File "/usr/local/lib/python3.6/dist-packages/redis/connection.py", line 494, in _connect
    raise err
  File "/usr/local/lib/python3.6/dist-packages/redis/connection.py", line 482, in _connect
    sock.connect(socket_address)
ConnectionRefusedError: [Errno 111] Connection refused

During handling of the above exception, another exception occurred:

Traceback (most recent call last):
  File "/usr/local/lib/python3.6/dist-packages/twisted/internet/defer.py", line 1418, in _inlineCallbacks
    result = g.send(result)
  File "/usr/local/lib/python3.6/dist-packages/scrapy/core/downloader/middleware.py", line 38, in process_request
    response = yield method(request=request, spider=spider)
  File "/home/jiangjin/桌面/xxoovideo/xxoovideo/middlewares.py", line 17, in process_request
    if self.bf.isContains(request.url):
  File "/home/jiangjin/桌面/xxoovideo/xxoovideo/tool/bloomfulter.py", line 50, in isContains
    ret = ret & self.server.getbit(name, loc)
  File "/usr/local/lib/python3.6/dist-packages/redis/client.py", line 894, in getbit
    return self.execute_command('GETBIT', name, offset)
  File "/usr/local/lib/python3.6/dist-packages/redis/client.py", line 578, in execute_command
    connection.send_command(*args)
  File "/usr/local/lib/python3.6/dist-packages/redis/connection.py", line 563, in send_command
    self.send_packed_command(self.pack_command(*args))
  File "/usr/local/lib/python3.6/dist-packages/redis/connection.py", line 538, in send_packed_command
    self.connect()
  File "/usr/local/lib/python3.6/dist-packages/redis/connection.py", line 442, in connect
    raise ConnectionError(self._error_message(e))
redis.exceptions.ConnectionError: Error 111 connecting to localhost:6379. Connection refused.
2020-02-08 23:35:36 [scrapy.core.scraper] ERROR: Error downloading <GET http://yj1.ceea3a8ea1f.pw/pw/html_data/111/2002/4598646.html>
Traceback (most recent call last):
  File "/usr/local/lib/python3.6/dist-packages/redis/connection.py", line 439, in connect
    sock = self._connect()
  File "/usr/local/lib/python3.6/dist-packages/redis/connection.py", line 494, in _connect
    raise err
  File "/usr/local/lib/python3.6/dist-packages/redis/connection.py", line 482, in _connect
    sock.connect(socket_address)
ConnectionRefusedError: [Errno 111] Connection refused

During handling of the above exception, another exception occurred:

Traceback (most recent call last):
  File "/usr/local/lib/python3.6/dist-packages/redis/client.py", line 572, in execute_command
    connection.send_command(*args)
  File "/usr/local/lib/python3.6/dist-packages/redis/connection.py", line 563, in send_command
    self.send_packed_command(self.pack_command(*args))
  File "/usr/local/lib/python3.6/dist-packages/redis/connection.py", line 538, in send_packed_command
    self.connect()
  File "/usr/local/lib/python3.6/dist-packages/redis/connection.py", line 442, in connect
    raise ConnectionError(self._error_message(e))
redis.exceptions.ConnectionError: Error 111 connecting to localhost:6379. Connection refused.

During handling of the above exception, another exception occurred:

Traceback (most recent call last):
  File "/usr/local/lib/python3.6/dist-packages/redis/connection.py", line 439, in connect
    sock = self._connect()
  File "/usr/local/lib/python3.6/dist-packages/redis/connection.py", line 494, in _connect
    raise err
  File "/usr/local/lib/python3.6/dist-packages/redis/connection.py", line 482, in _connect
    sock.connect(socket_address)
ConnectionRefusedError: [Errno 111] Connection refused

During handling of the above exception, another exception occurred:

Traceback (most recent call last):
  File "/usr/local/lib/python3.6/dist-packages/twisted/internet/defer.py", line 1418, in _inlineCallbacks
    result = g.send(result)
  File "/usr/local/lib/python3.6/dist-packages/scrapy/core/downloader/middleware.py", line 38, in process_request
    response = yield method(request=request, spider=spider)
  File "/home/jiangjin/桌面/xxoovideo/xxoovideo/middlewares.py", line 17, in process_request
    if self.bf.isContains(request.url):
  File "/home/jiangjin/桌面/xxoovideo/xxoovideo/tool/bloomfulter.py", line 50, in isContains
    ret = ret & self.server.getbit(name, loc)
  File "/usr/local/lib/python3.6/dist-packages/redis/client.py", line 894, in getbit
    return self.execute_command('GETBIT', name, offset)
  File "/usr/local/lib/python3.6/dist-packages/redis/client.py", line 578, in execute_command
    connection.send_command(*args)
  File "/usr/local/lib/python3.6/dist-packages/redis/connection.py", line 563, in send_command
    self.send_packed_command(self.pack_command(*args))
  File "/usr/local/lib/python3.6/dist-packages/redis/connection.py", line 538, in send_packed_command
    self.connect()
  File "/usr/local/lib/python3.6/dist-packages/redis/connection.py", line 442, in connect
    raise ConnectionError(self._error_message(e))
redis.exceptions.ConnectionError: Error 111 connecting to localhost:6379. Connection refused.
2020-02-08 23:35:36 [scrapy.core.scraper] ERROR: Error downloading <GET http://yj1.ceea3a8ea1f.pw/pw/html_data/111/2002/4598656.html>
Traceback (most recent call last):
  File "/usr/local/lib/python3.6/dist-packages/redis/connection.py", line 439, in connect
    sock = self._connect()
  File "/usr/local/lib/python3.6/dist-packages/redis/connection.py", line 494, in _connect
    raise err
  File "/usr/local/lib/python3.6/dist-packages/redis/connection.py", line 482, in _connect
    sock.connect(socket_address)
ConnectionRefusedError: [Errno 111] Connection refused

During handling of the above exception, another exception occurred:

Traceback (most recent call last):
  File "/usr/local/lib/python3.6/dist-packages/redis/client.py", line 572, in execute_command
    connection.send_command(*args)
  File "/usr/local/lib/python3.6/dist-packages/redis/connection.py", line 563, in send_command
    self.send_packed_command(self.pack_command(*args))
  File "/usr/local/lib/python3.6/dist-packages/redis/connection.py", line 538, in send_packed_command
    self.connect()
  File "/usr/local/lib/python3.6/dist-packages/redis/connection.py", line 442, in connect
    raise ConnectionError(self._error_message(e))
redis.exceptions.ConnectionError: Error 111 connecting to localhost:6379. Connection refused.

During handling of the above exception, another exception occurred:

Traceback (most recent call last):
  File "/usr/local/lib/python3.6/dist-packages/redis/connection.py", line 439, in connect
    sock = self._connect()
  File "/usr/local/lib/python3.6/dist-packages/redis/connection.py", line 494, in _connect
    raise err
  File "/usr/local/lib/python3.6/dist-packages/redis/connection.py", line 482, in _connect
    sock.connect(socket_address)
ConnectionRefusedError: [Errno 111] Connection refused

During handling of the above exception, another exception occurred:

Traceback (most recent call last):
  File "/usr/local/lib/python3.6/dist-packages/twisted/internet/defer.py", line 1418, in _inlineCallbacks
    result = g.send(result)
  File "/usr/local/lib/python3.6/dist-packages/scrapy/core/downloader/middleware.py", line 38, in process_request
    response = yield method(request=request, spider=spider)
  File "/home/jiangjin/桌面/xxoovideo/xxoovideo/middlewares.py", line 17, in process_request
    if self.bf.isContains(request.url):
  File "/home/jiangjin/桌面/xxoovideo/xxoovideo/tool/bloomfulter.py", line 50, in isContains
    ret = ret & self.server.getbit(name, loc)
  File "/usr/local/lib/python3.6/dist-packages/redis/client.py", line 894, in getbit
    return self.execute_command('GETBIT', name, offset)
  File "/usr/local/lib/python3.6/dist-packages/redis/client.py", line 578, in execute_command
    connection.send_command(*args)
  File "/usr/local/lib/python3.6/dist-packages/redis/connection.py", line 563, in send_command
    self.send_packed_command(self.pack_command(*args))
  File "/usr/local/lib/python3.6/dist-packages/redis/connection.py", line 538, in send_packed_command
    self.connect()
  File "/usr/local/lib/python3.6/dist-packages/redis/connection.py", line 442, in connect
    raise ConnectionError(self._error_message(e))
redis.exceptions.ConnectionError: Error 111 connecting to localhost:6379. Connection refused.
2020-02-08 23:35:36 [scrapy.core.scraper] ERROR: Error downloading <GET http://yj1.ceea3a8ea1f.pw/pw/html_data/111/2002/4598659.html>
Traceback (most recent call last):
  File "/usr/local/lib/python3.6/dist-packages/redis/connection.py", line 439, in connect
    sock = self._connect()
  File "/usr/local/lib/python3.6/dist-packages/redis/connection.py", line 494, in _connect
    raise err
  File "/usr/local/lib/python3.6/dist-packages/redis/connection.py", line 482, in _connect
    sock.connect(socket_address)
ConnectionRefusedError: [Errno 111] Connection refused

During handling of the above exception, another exception occurred:

Traceback (most recent call last):
  File "/usr/local/lib/python3.6/dist-packages/redis/client.py", line 572, in execute_command
    connection.send_command(*args)
  File "/usr/local/lib/python3.6/dist-packages/redis/connection.py", line 563, in send_command
    self.send_packed_command(self.pack_command(*args))
  File "/usr/local/lib/python3.6/dist-packages/redis/connection.py", line 538, in send_packed_command
    self.connect()
  File "/usr/local/lib/python3.6/dist-packages/redis/connection.py", line 442, in connect
    raise ConnectionError(self._error_message(e))
redis.exceptions.ConnectionError: Error 111 connecting to localhost:6379. Connection refused.

During handling of the above exception, another exception occurred:

Traceback (most recent call last):
  File "/usr/local/lib/python3.6/dist-packages/redis/connection.py", line 439, in connect
    sock = self._connect()
  File "/usr/local/lib/python3.6/dist-packages/redis/connection.py", line 494, in _connect
    raise err
  File "/usr/local/lib/python3.6/dist-packages/redis/connection.py", line 482, in _connect
    sock.connect(socket_address)
ConnectionRefusedError: [Errno 111] Connection refused

During handling of the above exception, another exception occurred:

Traceback (most recent call last):
  File "/usr/local/lib/python3.6/dist-packages/twisted/internet/defer.py", line 1418, in _inlineCallbacks
    result = g.send(result)
  File "/usr/local/lib/python3.6/dist-packages/scrapy/core/downloader/middleware.py", line 38, in process_request
    response = yield method(request=request, spider=spider)
  File "/home/jiangjin/桌面/xxoovideo/xxoovideo/middlewares.py", line 17, in process_request
    if self.bf.isContains(request.url):
  File "/home/jiangjin/桌面/xxoovideo/xxoovideo/tool/bloomfulter.py", line 50, in isContains
    ret = ret & self.server.getbit(name, loc)
  File "/usr/local/lib/python3.6/dist-packages/redis/client.py", line 894, in getbit
    return self.execute_command('GETBIT', name, offset)
  File "/usr/local/lib/python3.6/dist-packages/redis/client.py", line 578, in execute_command
    connection.send_command(*args)
  File "/usr/local/lib/python3.6/dist-packages/redis/connection.py", line 563, in send_command
    self.send_packed_command(self.pack_command(*args))
  File "/usr/local/lib/python3.6/dist-packages/redis/connection.py", line 538, in send_packed_command
    self.connect()
  File "/usr/local/lib/python3.6/dist-packages/redis/connection.py", line 442, in connect
    raise ConnectionError(self._error_message(e))
redis.exceptions.ConnectionError: Error 111 connecting to localhost:6379. Connection refused.
2020-02-08 23:35:36 [scrapy.core.scraper] ERROR: Error downloading <GET http://yj1.ceea3a8ea1f.pw/pw/html_data/111/2002/4598661.html>
Traceback (most recent call last):
  File "/usr/local/lib/python3.6/dist-packages/redis/connection.py", line 439, in connect
    sock = self._connect()
  File "/usr/local/lib/python3.6/dist-packages/redis/connection.py", line 494, in _connect
    raise err
  File "/usr/local/lib/python3.6/dist-packages/redis/connection.py", line 482, in _connect
    sock.connect(socket_address)
ConnectionRefusedError: [Errno 111] Connection refused

During handling of the above exception, another exception occurred:

Traceback (most recent call last):
  File "/usr/local/lib/python3.6/dist-packages/redis/client.py", line 572, in execute_command
    connection.send_command(*args)
  File "/usr/local/lib/python3.6/dist-packages/redis/connection.py", line 563, in send_command
    self.send_packed_command(self.pack_command(*args))
  File "/usr/local/lib/python3.6/dist-packages/redis/connection.py", line 538, in send_packed_command
    self.connect()
  File "/usr/local/lib/python3.6/dist-packages/redis/connection.py", line 442, in connect
    raise ConnectionError(self._error_message(e))
redis.exceptions.ConnectionError: Error 111 connecting to localhost:6379. Connection refused.

During handling of the above exception, another exception occurred:

Traceback (most recent call last):
  File "/usr/local/lib/python3.6/dist-packages/redis/connection.py", line 439, in connect
    sock = self._connect()
  File "/usr/local/lib/python3.6/dist-packages/redis/connection.py", line 494, in _connect
    raise err
  File "/usr/local/lib/python3.6/dist-packages/redis/connection.py", line 482, in _connect
    sock.connect(socket_address)
ConnectionRefusedError: [Errno 111] Connection refused

During handling of the above exception, another exception occurred:

Traceback (most recent call last):
  File "/usr/local/lib/python3.6/dist-packages/twisted/internet/defer.py", line 1418, in _inlineCallbacks
    result = g.send(result)
  File "/usr/local/lib/python3.6/dist-packages/scrapy/core/downloader/middleware.py", line 38, in process_request
    response = yield method(request=request, spider=spider)
  File "/home/jiangjin/桌面/xxoovideo/xxoovideo/middlewares.py", line 17, in process_request
    if self.bf.isContains(request.url):
  File "/home/jiangjin/桌面/xxoovideo/xxoovideo/tool/bloomfulter.py", line 50, in isContains
    ret = ret & self.server.getbit(name, loc)
  File "/usr/local/lib/python3.6/dist-packages/redis/client.py", line 894, in getbit
    return self.execute_command('GETBIT', name, offset)
  File "/usr/local/lib/python3.6/dist-packages/redis/client.py", line 578, in execute_command
    connection.send_command(*args)
  File "/usr/local/lib/python3.6/dist-packages/redis/connection.py", line 563, in send_command
    self.send_packed_command(self.pack_command(*args))
  File "/usr/local/lib/python3.6/dist-packages/redis/connection.py", line 538, in send_packed_command
    self.connect()
  File "/usr/local/lib/python3.6/dist-packages/redis/connection.py", line 442, in connect
    raise ConnectionError(self._error_message(e))
redis.exceptions.ConnectionError: Error 111 connecting to localhost:6379. Connection refused.
2020-02-08 23:35:36 [scrapy.core.scraper] ERROR: Error downloading <GET http://yj1.ceea3a8ea1f.pw/pw/html_data/111/2002/4598664.html>
Traceback (most recent call last):
  File "/usr/local/lib/python3.6/dist-packages/redis/connection.py", line 439, in connect
    sock = self._connect()
  File "/usr/local/lib/python3.6/dist-packages/redis/connection.py", line 494, in _connect
    raise err
  File "/usr/local/lib/python3.6/dist-packages/redis/connection.py", line 482, in _connect
    sock.connect(socket_address)
ConnectionRefusedError: [Errno 111] Connection refused

During handling of the above exception, another exception occurred:

Traceback (most recent call last):
  File "/usr/local/lib/python3.6/dist-packages/redis/client.py", line 572, in execute_command
    connection.send_command(*args)
  File "/usr/local/lib/python3.6/dist-packages/redis/connection.py", line 563, in send_command
    self.send_packed_command(self.pack_command(*args))
  File "/usr/local/lib/python3.6/dist-packages/redis/connection.py", line 538, in send_packed_command
    self.connect()
  File "/usr/local/lib/python3.6/dist-packages/redis/connection.py", line 442, in connect
    raise ConnectionError(self._error_message(e))
redis.exceptions.ConnectionError: Error 111 connecting to localhost:6379. Connection refused.

During handling of the above exception, another exception occurred:

Traceback (most recent call last):
  File "/usr/local/lib/python3.6/dist-packages/redis/connection.py", line 439, in connect
    sock = self._connect()
  File "/usr/local/lib/python3.6/dist-packages/redis/connection.py", line 494, in _connect
    raise err
  File "/usr/local/lib/python3.6/dist-packages/redis/connection.py", line 482, in _connect
    sock.connect(socket_address)
ConnectionRefusedError: [Errno 111] Connection refused

During handling of the above exception, another exception occurred:

Traceback (most recent call last):
  File "/usr/local/lib/python3.6/dist-packages/twisted/internet/defer.py", line 1418, in _inlineCallbacks
    result = g.send(result)
  File "/usr/local/lib/python3.6/dist-packages/scrapy/core/downloader/middleware.py", line 38, in process_request
    response = yield method(request=request, spider=spider)
  File "/home/jiangjin/桌面/xxoovideo/xxoovideo/middlewares.py", line 17, in process_request
    if self.bf.isContains(request.url):
  File "/home/jiangjin/桌面/xxoovideo/xxoovideo/tool/bloomfulter.py", line 50, in isContains
    ret = ret & self.server.getbit(name, loc)
  File "/usr/local/lib/python3.6/dist-packages/redis/client.py", line 894, in getbit
    return self.execute_command('GETBIT', name, offset)
  File "/usr/local/lib/python3.6/dist-packages/redis/client.py", line 578, in execute_command
    connection.send_command(*args)
  File "/usr/local/lib/python3.6/dist-packages/redis/connection.py", line 563, in send_command
    self.send_packed_command(self.pack_command(*args))
  File "/usr/local/lib/python3.6/dist-packages/redis/connection.py", line 538, in send_packed_command
    self.connect()
  File "/usr/local/lib/python3.6/dist-packages/redis/connection.py", line 442, in connect
    raise ConnectionError(self._error_message(e))
redis.exceptions.ConnectionError: Error 111 connecting to localhost:6379. Connection refused.
2020-02-08 23:35:36 [scrapy.core.scraper] ERROR: Error downloading <GET http://yj1.ceea3a8ea1f.pw/pw/html_data/111/2002/4598665.html>
Traceback (most recent call last):
  File "/usr/local/lib/python3.6/dist-packages/redis/connection.py", line 439, in connect
    sock = self._connect()
  File "/usr/local/lib/python3.6/dist-packages/redis/connection.py", line 494, in _connect
    raise err
  File "/usr/local/lib/python3.6/dist-packages/redis/connection.py", line 482, in _connect
    sock.connect(socket_address)
ConnectionRefusedError: [Errno 111] Connection refused

During handling of the above exception, another exception occurred:

Traceback (most recent call last):
  File "/usr/local/lib/python3.6/dist-packages/redis/client.py", line 572, in execute_command
    connection.send_command(*args)
  File "/usr/local/lib/python3.6/dist-packages/redis/connection.py", line 563, in send_command
    self.send_packed_command(self.pack_command(*args))
  File "/usr/local/lib/python3.6/dist-packages/redis/connection.py", line 538, in send_packed_command
    self.connect()
  File "/usr/local/lib/python3.6/dist-packages/redis/connection.py", line 442, in connect
    raise ConnectionError(self._error_message(e))
redis.exceptions.ConnectionError: Error 111 connecting to localhost:6379. Connection refused.

During handling of the above exception, another exception occurred:

Traceback (most recent call last):
  File "/usr/local/lib/python3.6/dist-packages/redis/connection.py", line 439, in connect
    sock = self._connect()
  File "/usr/local/lib/python3.6/dist-packages/redis/connection.py", line 494, in _connect
    raise err
  File "/usr/local/lib/python3.6/dist-packages/redis/connection.py", line 482, in _connect
    sock.connect(socket_address)
ConnectionRefusedError: [Errno 111] Connection refused

During handling of the above exception, another exception occurred:

Traceback (most recent call last):
  File "/usr/local/lib/python3.6/dist-packages/twisted/internet/defer.py", line 1418, in _inlineCallbacks
    result = g.send(result)
  File "/usr/local/lib/python3.6/dist-packages/scrapy/core/downloader/middleware.py", line 38, in process_request
    response = yield method(request=request, spider=spider)
  File "/home/jiangjin/桌面/xxoovideo/xxoovideo/middlewares.py", line 17, in process_request
    if self.bf.isContains(request.url):
  File "/home/jiangjin/桌面/xxoovideo/xxoovideo/tool/bloomfulter.py", line 50, in isContains
    ret = ret & self.server.getbit(name, loc)
  File "/usr/local/lib/python3.6/dist-packages/redis/client.py", line 894, in getbit
    return self.execute_command('GETBIT', name, offset)
  File "/usr/local/lib/python3.6/dist-packages/redis/client.py", line 578, in execute_command
    connection.send_command(*args)
  File "/usr/local/lib/python3.6/dist-packages/redis/connection.py", line 563, in send_command
    self.send_packed_command(self.pack_command(*args))
  File "/usr/local/lib/python3.6/dist-packages/redis/connection.py", line 538, in send_packed_command
    self.connect()
  File "/usr/local/lib/python3.6/dist-packages/redis/connection.py", line 442, in connect
    raise ConnectionError(self._error_message(e))
redis.exceptions.ConnectionError: Error 111 connecting to localhost:6379. Connection refused.
2020-02-08 23:35:36 [scrapy.core.scraper] ERROR: Error downloading <GET http://yj1.ceea3a8ea1f.pw/pw/html_data/111/2002/4598668.html>
Traceback (most recent call last):
  File "/usr/local/lib/python3.6/dist-packages/redis/connection.py", line 439, in connect
    sock = self._connect()
  File "/usr/local/lib/python3.6/dist-packages/redis/connection.py", line 494, in _connect
    raise err
  File "/usr/local/lib/python3.6/dist-packages/redis/connection.py", line 482, in _connect
    sock.connect(socket_address)
ConnectionRefusedError: [Errno 111] Connection refused

During handling of the above exception, another exception occurred:

Traceback (most recent call last):
  File "/usr/local/lib/python3.6/dist-packages/redis/client.py", line 572, in execute_command
    connection.send_command(*args)
  File "/usr/local/lib/python3.6/dist-packages/redis/connection.py", line 563, in send_command
    self.send_packed_command(self.pack_command(*args))
  File "/usr/local/lib/python3.6/dist-packages/redis/connection.py", line 538, in send_packed_command
    self.connect()
  File "/usr/local/lib/python3.6/dist-packages/redis/connection.py", line 442, in connect
    raise ConnectionError(self._error_message(e))
redis.exceptions.ConnectionError: Error 111 connecting to localhost:6379. Connection refused.

During handling of the above exception, another exception occurred:

Traceback (most recent call last):
  File "/usr/local/lib/python3.6/dist-packages/redis/connection.py", line 439, in connect
    sock = self._connect()
  File "/usr/local/lib/python3.6/dist-packages/redis/connection.py", line 494, in _connect
    raise err
  File "/usr/local/lib/python3.6/dist-packages/redis/connection.py", line 482, in _connect
    sock.connect(socket_address)
ConnectionRefusedError: [Errno 111] Connection refused

During handling of the above exception, another exception occurred:

Traceback (most recent call last):
  File "/usr/local/lib/python3.6/dist-packages/twisted/internet/defer.py", line 1418, in _inlineCallbacks
    result = g.send(result)
  File "/usr/local/lib/python3.6/dist-packages/scrapy/core/downloader/middleware.py", line 38, in process_request
    response = yield method(request=request, spider=spider)
  File "/home/jiangjin/桌面/xxoovideo/xxoovideo/middlewares.py", line 17, in process_request
    if self.bf.isContains(request.url):
  File "/home/jiangjin/桌面/xxoovideo/xxoovideo/tool/bloomfulter.py", line 50, in isContains
    ret = ret & self.server.getbit(name, loc)
  File "/usr/local/lib/python3.6/dist-packages/redis/client.py", line 894, in getbit
    return self.execute_command('GETBIT', name, offset)
  File "/usr/local/lib/python3.6/dist-packages/redis/client.py", line 578, in execute_command
    connection.send_command(*args)
  File "/usr/local/lib/python3.6/dist-packages/redis/connection.py", line 563, in send_command
    self.send_packed_command(self.pack_command(*args))
  File "/usr/local/lib/python3.6/dist-packages/redis/connection.py", line 538, in send_packed_command
    self.connect()
  File "/usr/local/lib/python3.6/dist-packages/redis/connection.py", line 442, in connect
    raise ConnectionError(self._error_message(e))
redis.exceptions.ConnectionError: Error 111 connecting to localhost:6379. Connection refused.
2020-02-08 23:35:36 [scrapy.core.scraper] ERROR: Error downloading <GET http://yj1.ceea3a8ea1f.pw/pw/html_data/111/2002/4598671.html>
Traceback (most recent call last):
  File "/usr/local/lib/python3.6/dist-packages/redis/connection.py", line 439, in connect
    sock = self._connect()
  File "/usr/local/lib/python3.6/dist-packages/redis/connection.py", line 494, in _connect
    raise err
  File "/usr/local/lib/python3.6/dist-packages/redis/connection.py", line 482, in _connect
    sock.connect(socket_address)
ConnectionRefusedError: [Errno 111] Connection refused

During handling of the above exception, another exception occurred:

Traceback (most recent call last):
  File "/usr/local/lib/python3.6/dist-packages/redis/client.py", line 572, in execute_command
    connection.send_command(*args)
  File "/usr/local/lib/python3.6/dist-packages/redis/connection.py", line 563, in send_command
    self.send_packed_command(self.pack_command(*args))
  File "/usr/local/lib/python3.6/dist-packages/redis/connection.py", line 538, in send_packed_command
    self.connect()
  File "/usr/local/lib/python3.6/dist-packages/redis/connection.py", line 442, in connect
    raise ConnectionError(self._error_message(e))
redis.exceptions.ConnectionError: Error 111 connecting to localhost:6379. Connection refused.

During handling of the above exception, another exception occurred:

Traceback (most recent call last):
  File "/usr/local/lib/python3.6/dist-packages/redis/connection.py", line 439, in connect
    sock = self._connect()
  File "/usr/local/lib/python3.6/dist-packages/redis/connection.py", line 494, in _connect
    raise err
  File "/usr/local/lib/python3.6/dist-packages/redis/connection.py", line 482, in _connect
    sock.connect(socket_address)
ConnectionRefusedError: [Errno 111] Connection refused

During handling of the above exception, another exception occurred:

Traceback (most recent call last):
  File "/usr/local/lib/python3.6/dist-packages/twisted/internet/defer.py", line 1418, in _inlineCallbacks
    result = g.send(result)
  File "/usr/local/lib/python3.6/dist-packages/scrapy/core/downloader/middleware.py", line 38, in process_request
    response = yield method(request=request, spider=spider)
  File "/home/jiangjin/桌面/xxoovideo/xxoovideo/middlewares.py", line 17, in process_request
    if self.bf.isContains(request.url):
  File "/home/jiangjin/桌面/xxoovideo/xxoovideo/tool/bloomfulter.py", line 50, in isContains
    ret = ret & self.server.getbit(name, loc)
  File "/usr/local/lib/python3.6/dist-packages/redis/client.py", line 894, in getbit
    return self.execute_command('GETBIT', name, offset)
  File "/usr/local/lib/python3.6/dist-packages/redis/client.py", line 578, in execute_command
    connection.send_command(*args)
  File "/usr/local/lib/python3.6/dist-packages/redis/connection.py", line 563, in send_command
    self.send_packed_command(self.pack_command(*args))
  File "/usr/local/lib/python3.6/dist-packages/redis/connection.py", line 538, in send_packed_command
    self.connect()
  File "/usr/local/lib/python3.6/dist-packages/redis/connection.py", line 442, in connect
    raise ConnectionError(self._error_message(e))
redis.exceptions.ConnectionError: Error 111 connecting to localhost:6379. Connection refused.
2020-02-08 23:35:36 [scrapy.core.scraper] ERROR: Error downloading <GET http://yj1.ceea3a8ea1f.pw/pw/html_data/111/2002/4598812.html>
Traceback (most recent call last):
  File "/usr/local/lib/python3.6/dist-packages/redis/connection.py", line 439, in connect
    sock = self._connect()
  File "/usr/local/lib/python3.6/dist-packages/redis/connection.py", line 494, in _connect
    raise err
  File "/usr/local/lib/python3.6/dist-packages/redis/connection.py", line 482, in _connect
    sock.connect(socket_address)
ConnectionRefusedError: [Errno 111] Connection refused

During handling of the above exception, another exception occurred:

Traceback (most recent call last):
  File "/usr/local/lib/python3.6/dist-packages/redis/client.py", line 572, in execute_command
    connection.send_command(*args)
  File "/usr/local/lib/python3.6/dist-packages/redis/connection.py", line 563, in send_command
    self.send_packed_command(self.pack_command(*args))
  File "/usr/local/lib/python3.6/dist-packages/redis/connection.py", line 538, in send_packed_command
    self.connect()
  File "/usr/local/lib/python3.6/dist-packages/redis/connection.py", line 442, in connect
    raise ConnectionError(self._error_message(e))
redis.exceptions.ConnectionError: Error 111 connecting to localhost:6379. Connection refused.

During handling of the above exception, another exception occurred:

Traceback (most recent call last):
  File "/usr/local/lib/python3.6/dist-packages/redis/connection.py", line 439, in connect
    sock = self._connect()
  File "/usr/local/lib/python3.6/dist-packages/redis/connection.py", line 494, in _connect
    raise err
  File "/usr/local/lib/python3.6/dist-packages/redis/connection.py", line 482, in _connect
    sock.connect(socket_address)
ConnectionRefusedError: [Errno 111] Connection refused

During handling of the above exception, another exception occurred:

Traceback (most recent call last):
  File "/usr/local/lib/python3.6/dist-packages/twisted/internet/defer.py", line 1418, in _inlineCallbacks
    result = g.send(result)
  File "/usr/local/lib/python3.6/dist-packages/scrapy/core/downloader/middleware.py", line 38, in process_request
    response = yield method(request=request, spider=spider)
  File "/home/jiangjin/桌面/xxoovideo/xxoovideo/middlewares.py", line 17, in process_request
    if self.bf.isContains(request.url):
  File "/home/jiangjin/桌面/xxoovideo/xxoovideo/tool/bloomfulter.py", line 50, in isContains
    ret = ret & self.server.getbit(name, loc)
  File "/usr/local/lib/python3.6/dist-packages/redis/client.py", line 894, in getbit
    return self.execute_command('GETBIT', name, offset)
  File "/usr/local/lib/python3.6/dist-packages/redis/client.py", line 578, in execute_command
    connection.send_command(*args)
  File "/usr/local/lib/python3.6/dist-packages/redis/connection.py", line 563, in send_command
    self.send_packed_command(self.pack_command(*args))
  File "/usr/local/lib/python3.6/dist-packages/redis/connection.py", line 538, in send_packed_command
    self.connect()
  File "/usr/local/lib/python3.6/dist-packages/redis/connection.py", line 442, in connect
    raise ConnectionError(self._error_message(e))
redis.exceptions.ConnectionError: Error 111 connecting to localhost:6379. Connection refused.
2020-02-08 23:35:36 [scrapy.core.scraper] ERROR: Error downloading <GET http://yj1.ceea3a8ea1f.pw/pw/html_data/111/2002/4598815.html>
Traceback (most recent call last):
  File "/usr/local/lib/python3.6/dist-packages/redis/connection.py", line 439, in connect
    sock = self._connect()
  File "/usr/local/lib/python3.6/dist-packages/redis/connection.py", line 494, in _connect
    raise err
  File "/usr/local/lib/python3.6/dist-packages/redis/connection.py", line 482, in _connect
    sock.connect(socket_address)
ConnectionRefusedError: [Errno 111] Connection refused

During handling of the above exception, another exception occurred:

Traceback (most recent call last):
  File "/usr/local/lib/python3.6/dist-packages/redis/client.py", line 572, in execute_command
    connection.send_command(*args)
  File "/usr/local/lib/python3.6/dist-packages/redis/connection.py", line 563, in send_command
    self.send_packed_command(self.pack_command(*args))
  File "/usr/local/lib/python3.6/dist-packages/redis/connection.py", line 538, in send_packed_command
    self.connect()
  File "/usr/local/lib/python3.6/dist-packages/redis/connection.py", line 442, in connect
    raise ConnectionError(self._error_message(e))
redis.exceptions.ConnectionError: Error 111 connecting to localhost:6379. Connection refused.

During handling of the above exception, another exception occurred:

Traceback (most recent call last):
  File "/usr/local/lib/python3.6/dist-packages/redis/connection.py", line 439, in connect
    sock = self._connect()
  File "/usr/local/lib/python3.6/dist-packages/redis/connection.py", line 494, in _connect
    raise err
  File "/usr/local/lib/python3.6/dist-packages/redis/connection.py", line 482, in _connect
    sock.connect(socket_address)
ConnectionRefusedError: [Errno 111] Connection refused

During handling of the above exception, another exception occurred:

Traceback (most recent call last):
  File "/usr/local/lib/python3.6/dist-packages/twisted/internet/defer.py", line 1418, in _inlineCallbacks
    result = g.send(result)
  File "/usr/local/lib/python3.6/dist-packages/scrapy/core/downloader/middleware.py", line 38, in process_request
    response = yield method(request=request, spider=spider)
  File "/home/jiangjin/桌面/xxoovideo/xxoovideo/middlewares.py", line 17, in process_request
    if self.bf.isContains(request.url):
  File "/home/jiangjin/桌面/xxoovideo/xxoovideo/tool/bloomfulter.py", line 50, in isContains
    ret = ret & self.server.getbit(name, loc)
  File "/usr/local/lib/python3.6/dist-packages/redis/client.py", line 894, in getbit
    return self.execute_command('GETBIT', name, offset)
  File "/usr/local/lib/python3.6/dist-packages/redis/client.py", line 578, in execute_command
    connection.send_command(*args)
  File "/usr/local/lib/python3.6/dist-packages/redis/connection.py", line 563, in send_command
    self.send_packed_command(self.pack_command(*args))
  File "/usr/local/lib/python3.6/dist-packages/redis/connection.py", line 538, in send_packed_command
    self.connect()
  File "/usr/local/lib/python3.6/dist-packages/redis/connection.py", line 442, in connect
    raise ConnectionError(self._error_message(e))
redis.exceptions.ConnectionError: Error 111 connecting to localhost:6379. Connection refused.
2020-02-08 23:35:36 [scrapy.core.scraper] ERROR: Error downloading <GET http://yj1.ceea3a8ea1f.pw/pw/html_data/111/2002/4598816.html>
Traceback (most recent call last):
  File "/usr/local/lib/python3.6/dist-packages/redis/connection.py", line 439, in connect
    sock = self._connect()
  File "/usr/local/lib/python3.6/dist-packages/redis/connection.py", line 494, in _connect
    raise err
  File "/usr/local/lib/python3.6/dist-packages/redis/connection.py", line 482, in _connect
    sock.connect(socket_address)
ConnectionRefusedError: [Errno 111] Connection refused

During handling of the above exception, another exception occurred:

Traceback (most recent call last):
  File "/usr/local/lib/python3.6/dist-packages/redis/client.py", line 572, in execute_command
    connection.send_command(*args)
  File "/usr/local/lib/python3.6/dist-packages/redis/connection.py", line 563, in send_command
    self.send_packed_command(self.pack_command(*args))
  File "/usr/local/lib/python3.6/dist-packages/redis/connection.py", line 538, in send_packed_command
    self.connect()
  File "/usr/local/lib/python3.6/dist-packages/redis/connection.py", line 442, in connect
    raise ConnectionError(self._error_message(e))
redis.exceptions.ConnectionError: Error 111 connecting to localhost:6379. Connection refused.

During handling of the above exception, another exception occurred:

Traceback (most recent call last):
  File "/usr/local/lib/python3.6/dist-packages/redis/connection.py", line 439, in connect
    sock = self._connect()
  File "/usr/local/lib/python3.6/dist-packages/redis/connection.py", line 494, in _connect
    raise err
  File "/usr/local/lib/python3.6/dist-packages/redis/connection.py", line 482, in _connect
    sock.connect(socket_address)
ConnectionRefusedError: [Errno 111] Connection refused

During handling of the above exception, another exception occurred:

Traceback (most recent call last):
  File "/usr/local/lib/python3.6/dist-packages/twisted/internet/defer.py", line 1418, in _inlineCallbacks
    result = g.send(result)
  File "/usr/local/lib/python3.6/dist-packages/scrapy/core/downloader/middleware.py", line 38, in process_request
    response = yield method(request=request, spider=spider)
  File "/home/jiangjin/桌面/xxoovideo/xxoovideo/middlewares.py", line 17, in process_request
    if self.bf.isContains(request.url):
  File "/home/jiangjin/桌面/xxoovideo/xxoovideo/tool/bloomfulter.py", line 50, in isContains
    ret = ret & self.server.getbit(name, loc)
  File "/usr/local/lib/python3.6/dist-packages/redis/client.py", line 894, in getbit
    return self.execute_command('GETBIT', name, offset)
  File "/usr/local/lib/python3.6/dist-packages/redis/client.py", line 578, in execute_command
    connection.send_command(*args)
  File "/usr/local/lib/python3.6/dist-packages/redis/connection.py", line 563, in send_command
    self.send_packed_command(self.pack_command(*args))
  File "/usr/local/lib/python3.6/dist-packages/redis/connection.py", line 538, in send_packed_command
    self.connect()
  File "/usr/local/lib/python3.6/dist-packages/redis/connection.py", line 442, in connect
    raise ConnectionError(self._error_message(e))
redis.exceptions.ConnectionError: Error 111 connecting to localhost:6379. Connection refused.
2020-02-08 23:35:36 [scrapy.core.scraper] ERROR: Error downloading <GET http://yj1.ceea3a8ea1f.pw/pw/html_data/111/2002/4598818.html>
Traceback (most recent call last):
  File "/usr/local/lib/python3.6/dist-packages/redis/connection.py", line 439, in connect
    sock = self._connect()
  File "/usr/local/lib/python3.6/dist-packages/redis/connection.py", line 494, in _connect
    raise err
  File "/usr/local/lib/python3.6/dist-packages/redis/connection.py", line 482, in _connect
    sock.connect(socket_address)
ConnectionRefusedError: [Errno 111] Connection refused

During handling of the above exception, another exception occurred:

Traceback (most recent call last):
  File "/usr/local/lib/python3.6/dist-packages/redis/client.py", line 572, in execute_command
    connection.send_command(*args)
  File "/usr/local/lib/python3.6/dist-packages/redis/connection.py", line 563, in send_command
    self.send_packed_command(self.pack_command(*args))
  File "/usr/local/lib/python3.6/dist-packages/redis/connection.py", line 538, in send_packed_command
    self.connect()
  File "/usr/local/lib/python3.6/dist-packages/redis/connection.py", line 442, in connect
    raise ConnectionError(self._error_message(e))
redis.exceptions.ConnectionError: Error 111 connecting to localhost:6379. Connection refused.

During handling of the above exception, another exception occurred:

Traceback (most recent call last):
  File "/usr/local/lib/python3.6/dist-packages/redis/connection.py", line 439, in connect
    sock = self._connect()
  File "/usr/local/lib/python3.6/dist-packages/redis/connection.py", line 494, in _connect
    raise err
  File "/usr/local/lib/python3.6/dist-packages/redis/connection.py", line 482, in _connect
    sock.connect(socket_address)
ConnectionRefusedError: [Errno 111] Connection refused

During handling of the above exception, another exception occurred:

Traceback (most recent call last):
  File "/usr/local/lib/python3.6/dist-packages/twisted/internet/defer.py", line 1418, in _inlineCallbacks
    result = g.send(result)
  File "/usr/local/lib/python3.6/dist-packages/scrapy/core/downloader/middleware.py", line 38, in process_request
    response = yield method(request=request, spider=spider)
  File "/home/jiangjin/桌面/xxoovideo/xxoovideo/middlewares.py", line 17, in process_request
    if self.bf.isContains(request.url):
  File "/home/jiangjin/桌面/xxoovideo/xxoovideo/tool/bloomfulter.py", line 50, in isContains
    ret = ret & self.server.getbit(name, loc)
  File "/usr/local/lib/python3.6/dist-packages/redis/client.py", line 894, in getbit
    return self.execute_command('GETBIT', name, offset)
  File "/usr/local/lib/python3.6/dist-packages/redis/client.py", line 578, in execute_command
    connection.send_command(*args)
  File "/usr/local/lib/python3.6/dist-packages/redis/connection.py", line 563, in send_command
    self.send_packed_command(self.pack_command(*args))
  File "/usr/local/lib/python3.6/dist-packages/redis/connection.py", line 538, in send_packed_command
    self.connect()
  File "/usr/local/lib/python3.6/dist-packages/redis/connection.py", line 442, in connect
    raise ConnectionError(self._error_message(e))
redis.exceptions.ConnectionError: Error 111 connecting to localhost:6379. Connection refused.
2020-02-08 23:35:36 [scrapy.core.scraper] ERROR: Error downloading <GET http://yj1.ceea3a8ea1f.pw/pw/html_data/111/2002/4598820.html>
Traceback (most recent call last):
  File "/usr/local/lib/python3.6/dist-packages/redis/connection.py", line 439, in connect
    sock = self._connect()
  File "/usr/local/lib/python3.6/dist-packages/redis/connection.py", line 494, in _connect
    raise err
  File "/usr/local/lib/python3.6/dist-packages/redis/connection.py", line 482, in _connect
    sock.connect(socket_address)
ConnectionRefusedError: [Errno 111] Connection refused

During handling of the above exception, another exception occurred:

Traceback (most recent call last):
  File "/usr/local/lib/python3.6/dist-packages/redis/client.py", line 572, in execute_command
    connection.send_command(*args)
  File "/usr/local/lib/python3.6/dist-packages/redis/connection.py", line 563, in send_command
    self.send_packed_command(self.pack_command(*args))
  File "/usr/local/lib/python3.6/dist-packages/redis/connection.py", line 538, in send_packed_command
    self.connect()
  File "/usr/local/lib/python3.6/dist-packages/redis/connection.py", line 442, in connect
    raise ConnectionError(self._error_message(e))
redis.exceptions.ConnectionError: Error 111 connecting to localhost:6379. Connection refused.

During handling of the above exception, another exception occurred:

Traceback (most recent call last):
  File "/usr/local/lib/python3.6/dist-packages/redis/connection.py", line 439, in connect
    sock = self._connect()
  File "/usr/local/lib/python3.6/dist-packages/redis/connection.py", line 494, in _connect
    raise err
  File "/usr/local/lib/python3.6/dist-packages/redis/connection.py", line 482, in _connect
    sock.connect(socket_address)
ConnectionRefusedError: [Errno 111] Connection refused

During handling of the above exception, another exception occurred:

Traceback (most recent call last):
  File "/usr/local/lib/python3.6/dist-packages/twisted/internet/defer.py", line 1418, in _inlineCallbacks
    result = g.send(result)
  File "/usr/local/lib/python3.6/dist-packages/scrapy/core/downloader/middleware.py", line 38, in process_request
    response = yield method(request=request, spider=spider)
  File "/home/jiangjin/桌面/xxoovideo/xxoovideo/middlewares.py", line 17, in process_request
    if self.bf.isContains(request.url):
  File "/home/jiangjin/桌面/xxoovideo/xxoovideo/tool/bloomfulter.py", line 50, in isContains
    ret = ret & self.server.getbit(name, loc)
  File "/usr/local/lib/python3.6/dist-packages/redis/client.py", line 894, in getbit
    return self.execute_command('GETBIT', name, offset)
  File "/usr/local/lib/python3.6/dist-packages/redis/client.py", line 578, in execute_command
    connection.send_command(*args)
  File "/usr/local/lib/python3.6/dist-packages/redis/connection.py", line 563, in send_command
    self.send_packed_command(self.pack_command(*args))
  File "/usr/local/lib/python3.6/dist-packages/redis/connection.py", line 538, in send_packed_command
    self.connect()
  File "/usr/local/lib/python3.6/dist-packages/redis/connection.py", line 442, in connect
    raise ConnectionError(self._error_message(e))
redis.exceptions.ConnectionError: Error 111 connecting to localhost:6379. Connection refused.
2020-02-08 23:35:36 [scrapy.core.scraper] ERROR: Error downloading <GET http://yj1.ceea3a8ea1f.pw/pw/html_data/111/2002/4598821.html>
Traceback (most recent call last):
  File "/usr/local/lib/python3.6/dist-packages/redis/connection.py", line 439, in connect
    sock = self._connect()
  File "/usr/local/lib/python3.6/dist-packages/redis/connection.py", line 494, in _connect
    raise err
  File "/usr/local/lib/python3.6/dist-packages/redis/connection.py", line 482, in _connect
    sock.connect(socket_address)
ConnectionRefusedError: [Errno 111] Connection refused

During handling of the above exception, another exception occurred:

Traceback (most recent call last):
  File "/usr/local/lib/python3.6/dist-packages/redis/client.py", line 572, in execute_command
    connection.send_command(*args)
  File "/usr/local/lib/python3.6/dist-packages/redis/connection.py", line 563, in send_command
    self.send_packed_command(self.pack_command(*args))
  File "/usr/local/lib/python3.6/dist-packages/redis/connection.py", line 538, in send_packed_command
    self.connect()
  File "/usr/local/lib/python3.6/dist-packages/redis/connection.py", line 442, in connect
    raise ConnectionError(self._error_message(e))
redis.exceptions.ConnectionError: Error 111 connecting to localhost:6379. Connection refused.

During handling of the above exception, another exception occurred:

Traceback (most recent call last):
  File "/usr/local/lib/python3.6/dist-packages/redis/connection.py", line 439, in connect
    sock = self._connect()
  File "/usr/local/lib/python3.6/dist-packages/redis/connection.py", line 494, in _connect
    raise err
  File "/usr/local/lib/python3.6/dist-packages/redis/connection.py", line 482, in _connect
    sock.connect(socket_address)
ConnectionRefusedError: [Errno 111] Connection refused

During handling of the above exception, another exception occurred:

Traceback (most recent call last):
  File "/usr/local/lib/python3.6/dist-packages/twisted/internet/defer.py", line 1418, in _inlineCallbacks
    result = g.send(result)
  File "/usr/local/lib/python3.6/dist-packages/scrapy/core/downloader/middleware.py", line 38, in process_request
    response = yield method(request=request, spider=spider)
  File "/home/jiangjin/桌面/xxoovideo/xxoovideo/middlewares.py", line 17, in process_request
    if self.bf.isContains(request.url):
  File "/home/jiangjin/桌面/xxoovideo/xxoovideo/tool/bloomfulter.py", line 50, in isContains
    ret = ret & self.server.getbit(name, loc)
  File "/usr/local/lib/python3.6/dist-packages/redis/client.py", line 894, in getbit
    return self.execute_command('GETBIT', name, offset)
  File "/usr/local/lib/python3.6/dist-packages/redis/client.py", line 578, in execute_command
    connection.send_command(*args)
  File "/usr/local/lib/python3.6/dist-packages/redis/connection.py", line 563, in send_command
    self.send_packed_command(self.pack_command(*args))
  File "/usr/local/lib/python3.6/dist-packages/redis/connection.py", line 538, in send_packed_command
    self.connect()
  File "/usr/local/lib/python3.6/dist-packages/redis/connection.py", line 442, in connect
    raise ConnectionError(self._error_message(e))
redis.exceptions.ConnectionError: Error 111 connecting to localhost:6379. Connection refused.
2020-02-08 23:35:36 [scrapy.core.scraper] ERROR: Error downloading <GET http://yj1.ceea3a8ea1f.pw/pw/html_data/111/2002/4598824.html>
Traceback (most recent call last):
  File "/usr/local/lib/python3.6/dist-packages/redis/connection.py", line 439, in connect
    sock = self._connect()
  File "/usr/local/lib/python3.6/dist-packages/redis/connection.py", line 494, in _connect
    raise err
  File "/usr/local/lib/python3.6/dist-packages/redis/connection.py", line 482, in _connect
    sock.connect(socket_address)
ConnectionRefusedError: [Errno 111] Connection refused

During handling of the above exception, another exception occurred:

Traceback (most recent call last):
  File "/usr/local/lib/python3.6/dist-packages/redis/client.py", line 572, in execute_command
    connection.send_command(*args)
  File "/usr/local/lib/python3.6/dist-packages/redis/connection.py", line 563, in send_command
    self.send_packed_command(self.pack_command(*args))
  File "/usr/local/lib/python3.6/dist-packages/redis/connection.py", line 538, in send_packed_command
    self.connect()
  File "/usr/local/lib/python3.6/dist-packages/redis/connection.py", line 442, in connect
    raise ConnectionError(self._error_message(e))
redis.exceptions.ConnectionError: Error 111 connecting to localhost:6379. Connection refused.

During handling of the above exception, another exception occurred:

Traceback (most recent call last):
  File "/usr/local/lib/python3.6/dist-packages/redis/connection.py", line 439, in connect
    sock = self._connect()
  File "/usr/local/lib/python3.6/dist-packages/redis/connection.py", line 494, in _connect
    raise err
  File "/usr/local/lib/python3.6/dist-packages/redis/connection.py", line 482, in _connect
    sock.connect(socket_address)
ConnectionRefusedError: [Errno 111] Connection refused

During handling of the above exception, another exception occurred:

Traceback (most recent call last):
  File "/usr/local/lib/python3.6/dist-packages/twisted/internet/defer.py", line 1418, in _inlineCallbacks
    result = g.send(result)
  File "/usr/local/lib/python3.6/dist-packages/scrapy/core/downloader/middleware.py", line 38, in process_request
    response = yield method(request=request, spider=spider)
  File "/home/jiangjin/桌面/xxoovideo/xxoovideo/middlewares.py", line 17, in process_request
    if self.bf.isContains(request.url):
  File "/home/jiangjin/桌面/xxoovideo/xxoovideo/tool/bloomfulter.py", line 50, in isContains
    ret = ret & self.server.getbit(name, loc)
  File "/usr/local/lib/python3.6/dist-packages/redis/client.py", line 894, in getbit
    return self.execute_command('GETBIT', name, offset)
  File "/usr/local/lib/python3.6/dist-packages/redis/client.py", line 578, in execute_command
    connection.send_command(*args)
  File "/usr/local/lib/python3.6/dist-packages/redis/connection.py", line 563, in send_command
    self.send_packed_command(self.pack_command(*args))
  File "/usr/local/lib/python3.6/dist-packages/redis/connection.py", line 538, in send_packed_command
    self.connect()
  File "/usr/local/lib/python3.6/dist-packages/redis/connection.py", line 442, in connect
    raise ConnectionError(self._error_message(e))
redis.exceptions.ConnectionError: Error 111 connecting to localhost:6379. Connection refused.
2020-02-08 23:35:36 [scrapy.core.scraper] ERROR: Error downloading <GET http://yj1.ceea3a8ea1f.pw/pw/html_data/111/2002/4598827.html>
Traceback (most recent call last):
  File "/usr/local/lib/python3.6/dist-packages/redis/connection.py", line 439, in connect
    sock = self._connect()
  File "/usr/local/lib/python3.6/dist-packages/redis/connection.py", line 494, in _connect
    raise err
  File "/usr/local/lib/python3.6/dist-packages/redis/connection.py", line 482, in _connect
    sock.connect(socket_address)
ConnectionRefusedError: [Errno 111] Connection refused

During handling of the above exception, another exception occurred:

Traceback (most recent call last):
  File "/usr/local/lib/python3.6/dist-packages/redis/client.py", line 572, in execute_command
    connection.send_command(*args)
  File "/usr/local/lib/python3.6/dist-packages/redis/connection.py", line 563, in send_command
    self.send_packed_command(self.pack_command(*args))
  File "/usr/local/lib/python3.6/dist-packages/redis/connection.py", line 538, in send_packed_command
    self.connect()
  File "/usr/local/lib/python3.6/dist-packages/redis/connection.py", line 442, in connect
    raise ConnectionError(self._error_message(e))
redis.exceptions.ConnectionError: Error 111 connecting to localhost:6379. Connection refused.

During handling of the above exception, another exception occurred:

Traceback (most recent call last):
  File "/usr/local/lib/python3.6/dist-packages/redis/connection.py", line 439, in connect
    sock = self._connect()
  File "/usr/local/lib/python3.6/dist-packages/redis/connection.py", line 494, in _connect
    raise err
  File "/usr/local/lib/python3.6/dist-packages/redis/connection.py", line 482, in _connect
    sock.connect(socket_address)
ConnectionRefusedError: [Errno 111] Connection refused

During handling of the above exception, another exception occurred:

Traceback (most recent call last):
  File "/usr/local/lib/python3.6/dist-packages/twisted/internet/defer.py", line 1418, in _inlineCallbacks
    result = g.send(result)
  File "/usr/local/lib/python3.6/dist-packages/scrapy/core/downloader/middleware.py", line 38, in process_request
    response = yield method(request=request, spider=spider)
  File "/home/jiangjin/桌面/xxoovideo/xxoovideo/middlewares.py", line 17, in process_request
    if self.bf.isContains(request.url):
  File "/home/jiangjin/桌面/xxoovideo/xxoovideo/tool/bloomfulter.py", line 50, in isContains
    ret = ret & self.server.getbit(name, loc)
  File "/usr/local/lib/python3.6/dist-packages/redis/client.py", line 894, in getbit
    return self.execute_command('GETBIT', name, offset)
  File "/usr/local/lib/python3.6/dist-packages/redis/client.py", line 578, in execute_command
    connection.send_command(*args)
  File "/usr/local/lib/python3.6/dist-packages/redis/connection.py", line 563, in send_command
    self.send_packed_command(self.pack_command(*args))
  File "/usr/local/lib/python3.6/dist-packages/redis/connection.py", line 538, in send_packed_command
    self.connect()
  File "/usr/local/lib/python3.6/dist-packages/redis/connection.py", line 442, in connect
    raise ConnectionError(self._error_message(e))
redis.exceptions.ConnectionError: Error 111 connecting to localhost:6379. Connection refused.
2020-02-08 23:35:36 [scrapy.core.scraper] ERROR: Error downloading <GET http://yj1.ceea3a8ea1f.pw/pw/html_data/111/2002/4598828.html>
Traceback (most recent call last):
  File "/usr/local/lib/python3.6/dist-packages/redis/connection.py", line 439, in connect
    sock = self._connect()
  File "/usr/local/lib/python3.6/dist-packages/redis/connection.py", line 494, in _connect
    raise err
  File "/usr/local/lib/python3.6/dist-packages/redis/connection.py", line 482, in _connect
    sock.connect(socket_address)
ConnectionRefusedError: [Errno 111] Connection refused

During handling of the above exception, another exception occurred:

Traceback (most recent call last):
  File "/usr/local/lib/python3.6/dist-packages/redis/client.py", line 572, in execute_command
    connection.send_command(*args)
  File "/usr/local/lib/python3.6/dist-packages/redis/connection.py", line 563, in send_command
    self.send_packed_command(self.pack_command(*args))
  File "/usr/local/lib/python3.6/dist-packages/redis/connection.py", line 538, in send_packed_command
    self.connect()
  File "/usr/local/lib/python3.6/dist-packages/redis/connection.py", line 442, in connect
    raise ConnectionError(self._error_message(e))
redis.exceptions.ConnectionError: Error 111 connecting to localhost:6379. Connection refused.

During handling of the above exception, another exception occurred:

Traceback (most recent call last):
  File "/usr/local/lib/python3.6/dist-packages/redis/connection.py", line 439, in connect
    sock = self._connect()
  File "/usr/local/lib/python3.6/dist-packages/redis/connection.py", line 494, in _connect
    raise err
  File "/usr/local/lib/python3.6/dist-packages/redis/connection.py", line 482, in _connect
    sock.connect(socket_address)
ConnectionRefusedError: [Errno 111] Connection refused

During handling of the above exception, another exception occurred:

Traceback (most recent call last):
  File "/usr/local/lib/python3.6/dist-packages/twisted/internet/defer.py", line 1418, in _inlineCallbacks
    result = g.send(result)
  File "/usr/local/lib/python3.6/dist-packages/scrapy/core/downloader/middleware.py", line 38, in process_request
    response = yield method(request=request, spider=spider)
  File "/home/jiangjin/桌面/xxoovideo/xxoovideo/middlewares.py", line 17, in process_request
    if self.bf.isContains(request.url):
  File "/home/jiangjin/桌面/xxoovideo/xxoovideo/tool/bloomfulter.py", line 50, in isContains
    ret = ret & self.server.getbit(name, loc)
  File "/usr/local/lib/python3.6/dist-packages/redis/client.py", line 894, in getbit
    return self.execute_command('GETBIT', name, offset)
  File "/usr/local/lib/python3.6/dist-packages/redis/client.py", line 578, in execute_command
    connection.send_command(*args)
  File "/usr/local/lib/python3.6/dist-packages/redis/connection.py", line 563, in send_command
    self.send_packed_command(self.pack_command(*args))
  File "/usr/local/lib/python3.6/dist-packages/redis/connection.py", line 538, in send_packed_command
    self.connect()
  File "/usr/local/lib/python3.6/dist-packages/redis/connection.py", line 442, in connect
    raise ConnectionError(self._error_message(e))
redis.exceptions.ConnectionError: Error 111 connecting to localhost:6379. Connection refused.
2020-02-08 23:35:36 [scrapy.core.scraper] ERROR: Error downloading <GET http://yj1.ceea3a8ea1f.pw/pw/html_data/111/2002/4598830.html>
Traceback (most recent call last):
  File "/usr/local/lib/python3.6/dist-packages/redis/connection.py", line 439, in connect
    sock = self._connect()
  File "/usr/local/lib/python3.6/dist-packages/redis/connection.py", line 494, in _connect
    raise err
  File "/usr/local/lib/python3.6/dist-packages/redis/connection.py", line 482, in _connect
    sock.connect(socket_address)
ConnectionRefusedError: [Errno 111] Connection refused

During handling of the above exception, another exception occurred:

Traceback (most recent call last):
  File "/usr/local/lib/python3.6/dist-packages/redis/client.py", line 572, in execute_command
    connection.send_command(*args)
  File "/usr/local/lib/python3.6/dist-packages/redis/connection.py", line 563, in send_command
    self.send_packed_command(self.pack_command(*args))
  File "/usr/local/lib/python3.6/dist-packages/redis/connection.py", line 538, in send_packed_command
    self.connect()
  File "/usr/local/lib/python3.6/dist-packages/redis/connection.py", line 442, in connect
    raise ConnectionError(self._error_message(e))
redis.exceptions.ConnectionError: Error 111 connecting to localhost:6379. Connection refused.

During handling of the above exception, another exception occurred:

Traceback (most recent call last):
  File "/usr/local/lib/python3.6/dist-packages/redis/connection.py", line 439, in connect
    sock = self._connect()
  File "/usr/local/lib/python3.6/dist-packages/redis/connection.py", line 494, in _connect
    raise err
  File "/usr/local/lib/python3.6/dist-packages/redis/connection.py", line 482, in _connect
    sock.connect(socket_address)
ConnectionRefusedError: [Errno 111] Connection refused

During handling of the above exception, another exception occurred:

Traceback (most recent call last):
  File "/usr/local/lib/python3.6/dist-packages/twisted/internet/defer.py", line 1418, in _inlineCallbacks
    result = g.send(result)
  File "/usr/local/lib/python3.6/dist-packages/scrapy/core/downloader/middleware.py", line 38, in process_request
    response = yield method(request=request, spider=spider)
  File "/home/jiangjin/桌面/xxoovideo/xxoovideo/middlewares.py", line 17, in process_request
    if self.bf.isContains(request.url):
  File "/home/jiangjin/桌面/xxoovideo/xxoovideo/tool/bloomfulter.py", line 50, in isContains
    ret = ret & self.server.getbit(name, loc)
  File "/usr/local/lib/python3.6/dist-packages/redis/client.py", line 894, in getbit
    return self.execute_command('GETBIT', name, offset)
  File "/usr/local/lib/python3.6/dist-packages/redis/client.py", line 578, in execute_command
    connection.send_command(*args)
  File "/usr/local/lib/python3.6/dist-packages/redis/connection.py", line 563, in send_command
    self.send_packed_command(self.pack_command(*args))
  File "/usr/local/lib/python3.6/dist-packages/redis/connection.py", line 538, in send_packed_command
    self.connect()
  File "/usr/local/lib/python3.6/dist-packages/redis/connection.py", line 442, in connect
    raise ConnectionError(self._error_message(e))
redis.exceptions.ConnectionError: Error 111 connecting to localhost:6379. Connection refused.
2020-02-08 23:35:36 [scrapy.core.scraper] ERROR: Error downloading <GET http://yj1.ceea3a8ea1f.pw/pw/html_data/111/2002/4598831.html>
Traceback (most recent call last):
  File "/usr/local/lib/python3.6/dist-packages/redis/connection.py", line 439, in connect
    sock = self._connect()
  File "/usr/local/lib/python3.6/dist-packages/redis/connection.py", line 494, in _connect
    raise err
  File "/usr/local/lib/python3.6/dist-packages/redis/connection.py", line 482, in _connect
    sock.connect(socket_address)
ConnectionRefusedError: [Errno 111] Connection refused

During handling of the above exception, another exception occurred:

Traceback (most recent call last):
  File "/usr/local/lib/python3.6/dist-packages/redis/client.py", line 572, in execute_command
    connection.send_command(*args)
  File "/usr/local/lib/python3.6/dist-packages/redis/connection.py", line 563, in send_command
    self.send_packed_command(self.pack_command(*args))
  File "/usr/local/lib/python3.6/dist-packages/redis/connection.py", line 538, in send_packed_command
    self.connect()
  File "/usr/local/lib/python3.6/dist-packages/redis/connection.py", line 442, in connect
    raise ConnectionError(self._error_message(e))
redis.exceptions.ConnectionError: Error 111 connecting to localhost:6379. Connection refused.

During handling of the above exception, another exception occurred:

Traceback (most recent call last):
  File "/usr/local/lib/python3.6/dist-packages/redis/connection.py", line 439, in connect
    sock = self._connect()
  File "/usr/local/lib/python3.6/dist-packages/redis/connection.py", line 494, in _connect
    raise err
  File "/usr/local/lib/python3.6/dist-packages/redis/connection.py", line 482, in _connect
    sock.connect(socket_address)
ConnectionRefusedError: [Errno 111] Connection refused

During handling of the above exception, another exception occurred:

Traceback (most recent call last):
  File "/usr/local/lib/python3.6/dist-packages/twisted/internet/defer.py", line 1418, in _inlineCallbacks
    result = g.send(result)
  File "/usr/local/lib/python3.6/dist-packages/scrapy/core/downloader/middleware.py", line 38, in process_request
    response = yield method(request=request, spider=spider)
  File "/home/jiangjin/桌面/xxoovideo/xxoovideo/middlewares.py", line 17, in process_request
    if self.bf.isContains(request.url):
  File "/home/jiangjin/桌面/xxoovideo/xxoovideo/tool/bloomfulter.py", line 50, in isContains
    ret = ret & self.server.getbit(name, loc)
  File "/usr/local/lib/python3.6/dist-packages/redis/client.py", line 894, in getbit
    return self.execute_command('GETBIT', name, offset)
  File "/usr/local/lib/python3.6/dist-packages/redis/client.py", line 578, in execute_command
    connection.send_command(*args)
  File "/usr/local/lib/python3.6/dist-packages/redis/connection.py", line 563, in send_command
    self.send_packed_command(self.pack_command(*args))
  File "/usr/local/lib/python3.6/dist-packages/redis/connection.py", line 538, in send_packed_command
    self.connect()
  File "/usr/local/lib/python3.6/dist-packages/redis/connection.py", line 442, in connect
    raise ConnectionError(self._error_message(e))
redis.exceptions.ConnectionError: Error 111 connecting to localhost:6379. Connection refused.
2020-02-08 23:35:36 [scrapy.core.scraper] ERROR: Error downloading <GET http://yj1.ceea3a8ea1f.pw/pw/html_data/111/2002/4598833.html>
Traceback (most recent call last):
  File "/usr/local/lib/python3.6/dist-packages/redis/connection.py", line 439, in connect
    sock = self._connect()
  File "/usr/local/lib/python3.6/dist-packages/redis/connection.py", line 494, in _connect
    raise err
  File "/usr/local/lib/python3.6/dist-packages/redis/connection.py", line 482, in _connect
    sock.connect(socket_address)
ConnectionRefusedError: [Errno 111] Connection refused

During handling of the above exception, another exception occurred:

Traceback (most recent call last):
  File "/usr/local/lib/python3.6/dist-packages/redis/client.py", line 572, in execute_command
    connection.send_command(*args)
  File "/usr/local/lib/python3.6/dist-packages/redis/connection.py", line 563, in send_command
    self.send_packed_command(self.pack_command(*args))
  File "/usr/local/lib/python3.6/dist-packages/redis/connection.py", line 538, in send_packed_command
    self.connect()
  File "/usr/local/lib/python3.6/dist-packages/redis/connection.py", line 442, in connect
    raise ConnectionError(self._error_message(e))
redis.exceptions.ConnectionError: Error 111 connecting to localhost:6379. Connection refused.

During handling of the above exception, another exception occurred:

Traceback (most recent call last):
  File "/usr/local/lib/python3.6/dist-packages/redis/connection.py", line 439, in connect
    sock = self._connect()
  File "/usr/local/lib/python3.6/dist-packages/redis/connection.py", line 494, in _connect
    raise err
  File "/usr/local/lib/python3.6/dist-packages/redis/connection.py", line 482, in _connect
    sock.connect(socket_address)
ConnectionRefusedError: [Errno 111] Connection refused

During handling of the above exception, another exception occurred:

Traceback (most recent call last):
  File "/usr/local/lib/python3.6/dist-packages/twisted/internet/defer.py", line 1418, in _inlineCallbacks
    result = g.send(result)
  File "/usr/local/lib/python3.6/dist-packages/scrapy/core/downloader/middleware.py", line 38, in process_request
    response = yield method(request=request, spider=spider)
  File "/home/jiangjin/桌面/xxoovideo/xxoovideo/middlewares.py", line 17, in process_request
    if self.bf.isContains(request.url):
  File "/home/jiangjin/桌面/xxoovideo/xxoovideo/tool/bloomfulter.py", line 50, in isContains
    ret = ret & self.server.getbit(name, loc)
  File "/usr/local/lib/python3.6/dist-packages/redis/client.py", line 894, in getbit
    return self.execute_command('GETBIT', name, offset)
  File "/usr/local/lib/python3.6/dist-packages/redis/client.py", line 578, in execute_command
    connection.send_command(*args)
  File "/usr/local/lib/python3.6/dist-packages/redis/connection.py", line 563, in send_command
    self.send_packed_command(self.pack_command(*args))
  File "/usr/local/lib/python3.6/dist-packages/redis/connection.py", line 538, in send_packed_command
    self.connect()
  File "/usr/local/lib/python3.6/dist-packages/redis/connection.py", line 442, in connect
    raise ConnectionError(self._error_message(e))
redis.exceptions.ConnectionError: Error 111 connecting to localhost:6379. Connection refused.
2020-02-08 23:35:36 [scrapy.core.scraper] ERROR: Error downloading <GET http://yj1.ceea3a8ea1f.pw/pw/html_data/111/2002/4599235.html>
Traceback (most recent call last):
  File "/usr/local/lib/python3.6/dist-packages/redis/connection.py", line 439, in connect
    sock = self._connect()
  File "/usr/local/lib/python3.6/dist-packages/redis/connection.py", line 494, in _connect
    raise err
  File "/usr/local/lib/python3.6/dist-packages/redis/connection.py", line 482, in _connect
    sock.connect(socket_address)
ConnectionRefusedError: [Errno 111] Connection refused

During handling of the above exception, another exception occurred:

Traceback (most recent call last):
  File "/usr/local/lib/python3.6/dist-packages/redis/client.py", line 572, in execute_command
    connection.send_command(*args)
  File "/usr/local/lib/python3.6/dist-packages/redis/connection.py", line 563, in send_command
    self.send_packed_command(self.pack_command(*args))
  File "/usr/local/lib/python3.6/dist-packages/redis/connection.py", line 538, in send_packed_command
    self.connect()
  File "/usr/local/lib/python3.6/dist-packages/redis/connection.py", line 442, in connect
    raise ConnectionError(self._error_message(e))
redis.exceptions.ConnectionError: Error 111 connecting to localhost:6379. Connection refused.

During handling of the above exception, another exception occurred:

Traceback (most recent call last):
  File "/usr/local/lib/python3.6/dist-packages/redis/connection.py", line 439, in connect
    sock = self._connect()
  File "/usr/local/lib/python3.6/dist-packages/redis/connection.py", line 494, in _connect
    raise err
  File "/usr/local/lib/python3.6/dist-packages/redis/connection.py", line 482, in _connect
    sock.connect(socket_address)
ConnectionRefusedError: [Errno 111] Connection refused

During handling of the above exception, another exception occurred:

Traceback (most recent call last):
  File "/usr/local/lib/python3.6/dist-packages/twisted/internet/defer.py", line 1418, in _inlineCallbacks
    result = g.send(result)
  File "/usr/local/lib/python3.6/dist-packages/scrapy/core/downloader/middleware.py", line 38, in process_request
    response = yield method(request=request, spider=spider)
  File "/home/jiangjin/桌面/xxoovideo/xxoovideo/middlewares.py", line 17, in process_request
    if self.bf.isContains(request.url):
  File "/home/jiangjin/桌面/xxoovideo/xxoovideo/tool/bloomfulter.py", line 50, in isContains
    ret = ret & self.server.getbit(name, loc)
  File "/usr/local/lib/python3.6/dist-packages/redis/client.py", line 894, in getbit
    return self.execute_command('GETBIT', name, offset)
  File "/usr/local/lib/python3.6/dist-packages/redis/client.py", line 578, in execute_command
    connection.send_command(*args)
  File "/usr/local/lib/python3.6/dist-packages/redis/connection.py", line 563, in send_command
    self.send_packed_command(self.pack_command(*args))
  File "/usr/local/lib/python3.6/dist-packages/redis/connection.py", line 538, in send_packed_command
    self.connect()
  File "/usr/local/lib/python3.6/dist-packages/redis/connection.py", line 442, in connect
    raise ConnectionError(self._error_message(e))
redis.exceptions.ConnectionError: Error 111 connecting to localhost:6379. Connection refused.
2020-02-08 23:35:36 [scrapy.core.scraper] ERROR: Error downloading <GET http://yj1.ceea3a8ea1f.pw/pw/html_data/111/2002/4599236.html>
Traceback (most recent call last):
  File "/usr/local/lib/python3.6/dist-packages/redis/connection.py", line 439, in connect
    sock = self._connect()
  File "/usr/local/lib/python3.6/dist-packages/redis/connection.py", line 494, in _connect
    raise err
  File "/usr/local/lib/python3.6/dist-packages/redis/connection.py", line 482, in _connect
    sock.connect(socket_address)
ConnectionRefusedError: [Errno 111] Connection refused

During handling of the above exception, another exception occurred:

Traceback (most recent call last):
  File "/usr/local/lib/python3.6/dist-packages/redis/client.py", line 572, in execute_command
    connection.send_command(*args)
  File "/usr/local/lib/python3.6/dist-packages/redis/connection.py", line 563, in send_command
    self.send_packed_command(self.pack_command(*args))
  File "/usr/local/lib/python3.6/dist-packages/redis/connection.py", line 538, in send_packed_command
    self.connect()
  File "/usr/local/lib/python3.6/dist-packages/redis/connection.py", line 442, in connect
    raise ConnectionError(self._error_message(e))
redis.exceptions.ConnectionError: Error 111 connecting to localhost:6379. Connection refused.

During handling of the above exception, another exception occurred:

Traceback (most recent call last):
  File "/usr/local/lib/python3.6/dist-packages/redis/connection.py", line 439, in connect
    sock = self._connect()
  File "/usr/local/lib/python3.6/dist-packages/redis/connection.py", line 494, in _connect
    raise err
  File "/usr/local/lib/python3.6/dist-packages/redis/connection.py", line 482, in _connect
    sock.connect(socket_address)
ConnectionRefusedError: [Errno 111] Connection refused

During handling of the above exception, another exception occurred:

Traceback (most recent call last):
  File "/usr/local/lib/python3.6/dist-packages/twisted/internet/defer.py", line 1418, in _inlineCallbacks
    result = g.send(result)
  File "/usr/local/lib/python3.6/dist-packages/scrapy/core/downloader/middleware.py", line 38, in process_request
    response = yield method(request=request, spider=spider)
  File "/home/jiangjin/桌面/xxoovideo/xxoovideo/middlewares.py", line 17, in process_request
    if self.bf.isContains(request.url):
  File "/home/jiangjin/桌面/xxoovideo/xxoovideo/tool/bloomfulter.py", line 50, in isContains
    ret = ret & self.server.getbit(name, loc)
  File "/usr/local/lib/python3.6/dist-packages/redis/client.py", line 894, in getbit
    return self.execute_command('GETBIT', name, offset)
  File "/usr/local/lib/python3.6/dist-packages/redis/client.py", line 578, in execute_command
    connection.send_command(*args)
  File "/usr/local/lib/python3.6/dist-packages/redis/connection.py", line 563, in send_command
    self.send_packed_command(self.pack_command(*args))
  File "/usr/local/lib/python3.6/dist-packages/redis/connection.py", line 538, in send_packed_command
    self.connect()
  File "/usr/local/lib/python3.6/dist-packages/redis/connection.py", line 442, in connect
    raise ConnectionError(self._error_message(e))
redis.exceptions.ConnectionError: Error 111 connecting to localhost:6379. Connection refused.
2020-02-08 23:35:36 [scrapy.core.scraper] ERROR: Error downloading <GET http://yj1.ceea3a8ea1f.pw/pw/html_data/111/2002/4599237.html>
Traceback (most recent call last):
  File "/usr/local/lib/python3.6/dist-packages/redis/connection.py", line 439, in connect
    sock = self._connect()
  File "/usr/local/lib/python3.6/dist-packages/redis/connection.py", line 494, in _connect
    raise err
  File "/usr/local/lib/python3.6/dist-packages/redis/connection.py", line 482, in _connect
    sock.connect(socket_address)
ConnectionRefusedError: [Errno 111] Connection refused

During handling of the above exception, another exception occurred:

Traceback (most recent call last):
  File "/usr/local/lib/python3.6/dist-packages/redis/client.py", line 572, in execute_command
    connection.send_command(*args)
  File "/usr/local/lib/python3.6/dist-packages/redis/connection.py", line 563, in send_command
    self.send_packed_command(self.pack_command(*args))
  File "/usr/local/lib/python3.6/dist-packages/redis/connection.py", line 538, in send_packed_command
    self.connect()
  File "/usr/local/lib/python3.6/dist-packages/redis/connection.py", line 442, in connect
    raise ConnectionError(self._error_message(e))
redis.exceptions.ConnectionError: Error 111 connecting to localhost:6379. Connection refused.

During handling of the above exception, another exception occurred:

Traceback (most recent call last):
  File "/usr/local/lib/python3.6/dist-packages/redis/connection.py", line 439, in connect
    sock = self._connect()
  File "/usr/local/lib/python3.6/dist-packages/redis/connection.py", line 494, in _connect
    raise err
  File "/usr/local/lib/python3.6/dist-packages/redis/connection.py", line 482, in _connect
    sock.connect(socket_address)
ConnectionRefusedError: [Errno 111] Connection refused

During handling of the above exception, another exception occurred:

Traceback (most recent call last):
  File "/usr/local/lib/python3.6/dist-packages/twisted/internet/defer.py", line 1418, in _inlineCallbacks
    result = g.send(result)
  File "/usr/local/lib/python3.6/dist-packages/scrapy/core/downloader/middleware.py", line 38, in process_request
    response = yield method(request=request, spider=spider)
  File "/home/jiangjin/桌面/xxoovideo/xxoovideo/middlewares.py", line 17, in process_request
    if self.bf.isContains(request.url):
  File "/home/jiangjin/桌面/xxoovideo/xxoovideo/tool/bloomfulter.py", line 50, in isContains
    ret = ret & self.server.getbit(name, loc)
  File "/usr/local/lib/python3.6/dist-packages/redis/client.py", line 894, in getbit
    return self.execute_command('GETBIT', name, offset)
  File "/usr/local/lib/python3.6/dist-packages/redis/client.py", line 578, in execute_command
    connection.send_command(*args)
  File "/usr/local/lib/python3.6/dist-packages/redis/connection.py", line 563, in send_command
    self.send_packed_command(self.pack_command(*args))
  File "/usr/local/lib/python3.6/dist-packages/redis/connection.py", line 538, in send_packed_command
    self.connect()
  File "/usr/local/lib/python3.6/dist-packages/redis/connection.py", line 442, in connect
    raise ConnectionError(self._error_message(e))
redis.exceptions.ConnectionError: Error 111 connecting to localhost:6379. Connection refused.
2020-02-08 23:35:36 [scrapy.core.scraper] ERROR: Error downloading <GET http://yj1.ceea3a8ea1f.pw/pw/html_data/111/2002/4599238.html>
Traceback (most recent call last):
  File "/usr/local/lib/python3.6/dist-packages/redis/connection.py", line 439, in connect
    sock = self._connect()
  File "/usr/local/lib/python3.6/dist-packages/redis/connection.py", line 494, in _connect
    raise err
  File "/usr/local/lib/python3.6/dist-packages/redis/connection.py", line 482, in _connect
    sock.connect(socket_address)
ConnectionRefusedError: [Errno 111] Connection refused

During handling of the above exception, another exception occurred:

Traceback (most recent call last):
  File "/usr/local/lib/python3.6/dist-packages/redis/client.py", line 572, in execute_command
    connection.send_command(*args)
  File "/usr/local/lib/python3.6/dist-packages/redis/connection.py", line 563, in send_command
    self.send_packed_command(self.pack_command(*args))
  File "/usr/local/lib/python3.6/dist-packages/redis/connection.py", line 538, in send_packed_command
    self.connect()
  File "/usr/local/lib/python3.6/dist-packages/redis/connection.py", line 442, in connect
    raise ConnectionError(self._error_message(e))
redis.exceptions.ConnectionError: Error 111 connecting to localhost:6379. Connection refused.

During handling of the above exception, another exception occurred:

Traceback (most recent call last):
  File "/usr/local/lib/python3.6/dist-packages/redis/connection.py", line 439, in connect
    sock = self._connect()
  File "/usr/local/lib/python3.6/dist-packages/redis/connection.py", line 494, in _connect
    raise err
  File "/usr/local/lib/python3.6/dist-packages/redis/connection.py", line 482, in _connect
    sock.connect(socket_address)
ConnectionRefusedError: [Errno 111] Connection refused

During handling of the above exception, another exception occurred:

Traceback (most recent call last):
  File "/usr/local/lib/python3.6/dist-packages/twisted/internet/defer.py", line 1418, in _inlineCallbacks
    result = g.send(result)
  File "/usr/local/lib/python3.6/dist-packages/scrapy/core/downloader/middleware.py", line 38, in process_request
    response = yield method(request=request, spider=spider)
  File "/home/jiangjin/桌面/xxoovideo/xxoovideo/middlewares.py", line 17, in process_request
    if self.bf.isContains(request.url):
  File "/home/jiangjin/桌面/xxoovideo/xxoovideo/tool/bloomfulter.py", line 50, in isContains
    ret = ret & self.server.getbit(name, loc)
  File "/usr/local/lib/python3.6/dist-packages/redis/client.py", line 894, in getbit
    return self.execute_command('GETBIT', name, offset)
  File "/usr/local/lib/python3.6/dist-packages/redis/client.py", line 578, in execute_command
    connection.send_command(*args)
  File "/usr/local/lib/python3.6/dist-packages/redis/connection.py", line 563, in send_command
    self.send_packed_command(self.pack_command(*args))
  File "/usr/local/lib/python3.6/dist-packages/redis/connection.py", line 538, in send_packed_command
    self.connect()
  File "/usr/local/lib/python3.6/dist-packages/redis/connection.py", line 442, in connect
    raise ConnectionError(self._error_message(e))
redis.exceptions.ConnectionError: Error 111 connecting to localhost:6379. Connection refused.
2020-02-08 23:35:36 [scrapy.core.scraper] ERROR: Error downloading <GET http://yj1.ceea3a8ea1f.pw/pw/html_data/111/2002/4599239.html>
Traceback (most recent call last):
  File "/usr/local/lib/python3.6/dist-packages/redis/connection.py", line 439, in connect
    sock = self._connect()
  File "/usr/local/lib/python3.6/dist-packages/redis/connection.py", line 494, in _connect
    raise err
  File "/usr/local/lib/python3.6/dist-packages/redis/connection.py", line 482, in _connect
    sock.connect(socket_address)
ConnectionRefusedError: [Errno 111] Connection refused

During handling of the above exception, another exception occurred:

Traceback (most recent call last):
  File "/usr/local/lib/python3.6/dist-packages/redis/client.py", line 572, in execute_command
    connection.send_command(*args)
  File "/usr/local/lib/python3.6/dist-packages/redis/connection.py", line 563, in send_command
    self.send_packed_command(self.pack_command(*args))
  File "/usr/local/lib/python3.6/dist-packages/redis/connection.py", line 538, in send_packed_command
    self.connect()
  File "/usr/local/lib/python3.6/dist-packages/redis/connection.py", line 442, in connect
    raise ConnectionError(self._error_message(e))
redis.exceptions.ConnectionError: Error 111 connecting to localhost:6379. Connection refused.

During handling of the above exception, another exception occurred:

Traceback (most recent call last):
  File "/usr/local/lib/python3.6/dist-packages/redis/connection.py", line 439, in connect
    sock = self._connect()
  File "/usr/local/lib/python3.6/dist-packages/redis/connection.py", line 494, in _connect
    raise err
  File "/usr/local/lib/python3.6/dist-packages/redis/connection.py", line 482, in _connect
    sock.connect(socket_address)
ConnectionRefusedError: [Errno 111] Connection refused

During handling of the above exception, another exception occurred:

Traceback (most recent call last):
  File "/usr/local/lib/python3.6/dist-packages/twisted/internet/defer.py", line 1418, in _inlineCallbacks
    result = g.send(result)
  File "/usr/local/lib/python3.6/dist-packages/scrapy/core/downloader/middleware.py", line 38, in process_request
    response = yield method(request=request, spider=spider)
  File "/home/jiangjin/桌面/xxoovideo/xxoovideo/middlewares.py", line 17, in process_request
    if self.bf.isContains(request.url):
  File "/home/jiangjin/桌面/xxoovideo/xxoovideo/tool/bloomfulter.py", line 50, in isContains
    ret = ret & self.server.getbit(name, loc)
  File "/usr/local/lib/python3.6/dist-packages/redis/client.py", line 894, in getbit
    return self.execute_command('GETBIT', name, offset)
  File "/usr/local/lib/python3.6/dist-packages/redis/client.py", line 578, in execute_command
    connection.send_command(*args)
  File "/usr/local/lib/python3.6/dist-packages/redis/connection.py", line 563, in send_command
    self.send_packed_command(self.pack_command(*args))
  File "/usr/local/lib/python3.6/dist-packages/redis/connection.py", line 538, in send_packed_command
    self.connect()
  File "/usr/local/lib/python3.6/dist-packages/redis/connection.py", line 442, in connect
    raise ConnectionError(self._error_message(e))
redis.exceptions.ConnectionError: Error 111 connecting to localhost:6379. Connection refused.
2020-02-08 23:35:36 [scrapy.core.scraper] ERROR: Error downloading <GET http://yj1.ceea3a8ea1f.pw/pw/html_data/111/2002/4599240.html>
Traceback (most recent call last):
  File "/usr/local/lib/python3.6/dist-packages/redis/connection.py", line 439, in connect
    sock = self._connect()
  File "/usr/local/lib/python3.6/dist-packages/redis/connection.py", line 494, in _connect
    raise err
  File "/usr/local/lib/python3.6/dist-packages/redis/connection.py", line 482, in _connect
    sock.connect(socket_address)
ConnectionRefusedError: [Errno 111] Connection refused

During handling of the above exception, another exception occurred:

Traceback (most recent call last):
  File "/usr/local/lib/python3.6/dist-packages/redis/client.py", line 572, in execute_command
    connection.send_command(*args)
  File "/usr/local/lib/python3.6/dist-packages/redis/connection.py", line 563, in send_command
    self.send_packed_command(self.pack_command(*args))
  File "/usr/local/lib/python3.6/dist-packages/redis/connection.py", line 538, in send_packed_command
    self.connect()
  File "/usr/local/lib/python3.6/dist-packages/redis/connection.py", line 442, in connect
    raise ConnectionError(self._error_message(e))
redis.exceptions.ConnectionError: Error 111 connecting to localhost:6379. Connection refused.

During handling of the above exception, another exception occurred:

Traceback (most recent call last):
  File "/usr/local/lib/python3.6/dist-packages/redis/connection.py", line 439, in connect
    sock = self._connect()
  File "/usr/local/lib/python3.6/dist-packages/redis/connection.py", line 494, in _connect
    raise err
  File "/usr/local/lib/python3.6/dist-packages/redis/connection.py", line 482, in _connect
    sock.connect(socket_address)
ConnectionRefusedError: [Errno 111] Connection refused

During handling of the above exception, another exception occurred:

Traceback (most recent call last):
  File "/usr/local/lib/python3.6/dist-packages/twisted/internet/defer.py", line 1418, in _inlineCallbacks
    result = g.send(result)
  File "/usr/local/lib/python3.6/dist-packages/scrapy/core/downloader/middleware.py", line 38, in process_request
    response = yield method(request=request, spider=spider)
  File "/home/jiangjin/桌面/xxoovideo/xxoovideo/middlewares.py", line 17, in process_request
    if self.bf.isContains(request.url):
  File "/home/jiangjin/桌面/xxoovideo/xxoovideo/tool/bloomfulter.py", line 50, in isContains
    ret = ret & self.server.getbit(name, loc)
  File "/usr/local/lib/python3.6/dist-packages/redis/client.py", line 894, in getbit
    return self.execute_command('GETBIT', name, offset)
  File "/usr/local/lib/python3.6/dist-packages/redis/client.py", line 578, in execute_command
    connection.send_command(*args)
  File "/usr/local/lib/python3.6/dist-packages/redis/connection.py", line 563, in send_command
    self.send_packed_command(self.pack_command(*args))
  File "/usr/local/lib/python3.6/dist-packages/redis/connection.py", line 538, in send_packed_command
    self.connect()
  File "/usr/local/lib/python3.6/dist-packages/redis/connection.py", line 442, in connect
    raise ConnectionError(self._error_message(e))
redis.exceptions.ConnectionError: Error 111 connecting to localhost:6379. Connection refused.
2020-02-08 23:35:36 [scrapy.core.scraper] ERROR: Error downloading <GET http://yj1.ceea3a8ea1f.pw/pw/html_data/111/2002/4599241.html>
Traceback (most recent call last):
  File "/usr/local/lib/python3.6/dist-packages/redis/connection.py", line 439, in connect
    sock = self._connect()
  File "/usr/local/lib/python3.6/dist-packages/redis/connection.py", line 494, in _connect
    raise err
  File "/usr/local/lib/python3.6/dist-packages/redis/connection.py", line 482, in _connect
    sock.connect(socket_address)
ConnectionRefusedError: [Errno 111] Connection refused

During handling of the above exception, another exception occurred:

Traceback (most recent call last):
  File "/usr/local/lib/python3.6/dist-packages/redis/client.py", line 572, in execute_command
    connection.send_command(*args)
  File "/usr/local/lib/python3.6/dist-packages/redis/connection.py", line 563, in send_command
    self.send_packed_command(self.pack_command(*args))
  File "/usr/local/lib/python3.6/dist-packages/redis/connection.py", line 538, in send_packed_command
    self.connect()
  File "/usr/local/lib/python3.6/dist-packages/redis/connection.py", line 442, in connect
    raise ConnectionError(self._error_message(e))
redis.exceptions.ConnectionError: Error 111 connecting to localhost:6379. Connection refused.

During handling of the above exception, another exception occurred:

Traceback (most recent call last):
  File "/usr/local/lib/python3.6/dist-packages/redis/connection.py", line 439, in connect
    sock = self._connect()
  File "/usr/local/lib/python3.6/dist-packages/redis/connection.py", line 494, in _connect
    raise err
  File "/usr/local/lib/python3.6/dist-packages/redis/connection.py", line 482, in _connect
    sock.connect(socket_address)
ConnectionRefusedError: [Errno 111] Connection refused

During handling of the above exception, another exception occurred:

Traceback (most recent call last):
  File "/usr/local/lib/python3.6/dist-packages/twisted/internet/defer.py", line 1418, in _inlineCallbacks
    result = g.send(result)
  File "/usr/local/lib/python3.6/dist-packages/scrapy/core/downloader/middleware.py", line 38, in process_request
    response = yield method(request=request, spider=spider)
  File "/home/jiangjin/桌面/xxoovideo/xxoovideo/middlewares.py", line 17, in process_request
    if self.bf.isContains(request.url):
  File "/home/jiangjin/桌面/xxoovideo/xxoovideo/tool/bloomfulter.py", line 50, in isContains
    ret = ret & self.server.getbit(name, loc)
  File "/usr/local/lib/python3.6/dist-packages/redis/client.py", line 894, in getbit
    return self.execute_command('GETBIT', name, offset)
  File "/usr/local/lib/python3.6/dist-packages/redis/client.py", line 578, in execute_command
    connection.send_command(*args)
  File "/usr/local/lib/python3.6/dist-packages/redis/connection.py", line 563, in send_command
    self.send_packed_command(self.pack_command(*args))
  File "/usr/local/lib/python3.6/dist-packages/redis/connection.py", line 538, in send_packed_command
    self.connect()
  File "/usr/local/lib/python3.6/dist-packages/redis/connection.py", line 442, in connect
    raise ConnectionError(self._error_message(e))
redis.exceptions.ConnectionError: Error 111 connecting to localhost:6379. Connection refused.
2020-02-08 23:35:36 [scrapy.core.scraper] ERROR: Error downloading <GET http://yj1.ceea3a8ea1f.pw/pw/html_data/111/2002/4599242.html>
Traceback (most recent call last):
  File "/usr/local/lib/python3.6/dist-packages/redis/connection.py", line 439, in connect
    sock = self._connect()
  File "/usr/local/lib/python3.6/dist-packages/redis/connection.py", line 494, in _connect
    raise err
  File "/usr/local/lib/python3.6/dist-packages/redis/connection.py", line 482, in _connect
    sock.connect(socket_address)
ConnectionRefusedError: [Errno 111] Connection refused

During handling of the above exception, another exception occurred:

Traceback (most recent call last):
  File "/usr/local/lib/python3.6/dist-packages/redis/client.py", line 572, in execute_command
    connection.send_command(*args)
  File "/usr/local/lib/python3.6/dist-packages/redis/connection.py", line 563, in send_command
    self.send_packed_command(self.pack_command(*args))
  File "/usr/local/lib/python3.6/dist-packages/redis/connection.py", line 538, in send_packed_command
    self.connect()
  File "/usr/local/lib/python3.6/dist-packages/redis/connection.py", line 442, in connect
    raise ConnectionError(self._error_message(e))
redis.exceptions.ConnectionError: Error 111 connecting to localhost:6379. Connection refused.

During handling of the above exception, another exception occurred:

Traceback (most recent call last):
  File "/usr/local/lib/python3.6/dist-packages/redis/connection.py", line 439, in connect
    sock = self._connect()
  File "/usr/local/lib/python3.6/dist-packages/redis/connection.py", line 494, in _connect
    raise err
  File "/usr/local/lib/python3.6/dist-packages/redis/connection.py", line 482, in _connect
    sock.connect(socket_address)
ConnectionRefusedError: [Errno 111] Connection refused

During handling of the above exception, another exception occurred:

Traceback (most recent call last):
  File "/usr/local/lib/python3.6/dist-packages/twisted/internet/defer.py", line 1418, in _inlineCallbacks
    result = g.send(result)
  File "/usr/local/lib/python3.6/dist-packages/scrapy/core/downloader/middleware.py", line 38, in process_request
    response = yield method(request=request, spider=spider)
  File "/home/jiangjin/桌面/xxoovideo/xxoovideo/middlewares.py", line 17, in process_request
    if self.bf.isContains(request.url):
  File "/home/jiangjin/桌面/xxoovideo/xxoovideo/tool/bloomfulter.py", line 50, in isContains
    ret = ret & self.server.getbit(name, loc)
  File "/usr/local/lib/python3.6/dist-packages/redis/client.py", line 894, in getbit
    return self.execute_command('GETBIT', name, offset)
  File "/usr/local/lib/python3.6/dist-packages/redis/client.py", line 578, in execute_command
    connection.send_command(*args)
  File "/usr/local/lib/python3.6/dist-packages/redis/connection.py", line 563, in send_command
    self.send_packed_command(self.pack_command(*args))
  File "/usr/local/lib/python3.6/dist-packages/redis/connection.py", line 538, in send_packed_command
    self.connect()
  File "/usr/local/lib/python3.6/dist-packages/redis/connection.py", line 442, in connect
    raise ConnectionError(self._error_message(e))
redis.exceptions.ConnectionError: Error 111 connecting to localhost:6379. Connection refused.
2020-02-08 23:35:36 [scrapy.core.scraper] ERROR: Error downloading <GET http://yj1.ceea3a8ea1f.pw/pw/html_data/111/2002/4599243.html>
Traceback (most recent call last):
  File "/usr/local/lib/python3.6/dist-packages/redis/connection.py", line 439, in connect
    sock = self._connect()
  File "/usr/local/lib/python3.6/dist-packages/redis/connection.py", line 494, in _connect
    raise err
  File "/usr/local/lib/python3.6/dist-packages/redis/connection.py", line 482, in _connect
    sock.connect(socket_address)
ConnectionRefusedError: [Errno 111] Connection refused

During handling of the above exception, another exception occurred:

Traceback (most recent call last):
  File "/usr/local/lib/python3.6/dist-packages/redis/client.py", line 572, in execute_command
    connection.send_command(*args)
  File "/usr/local/lib/python3.6/dist-packages/redis/connection.py", line 563, in send_command
    self.send_packed_command(self.pack_command(*args))
  File "/usr/local/lib/python3.6/dist-packages/redis/connection.py", line 538, in send_packed_command
    self.connect()
  File "/usr/local/lib/python3.6/dist-packages/redis/connection.py", line 442, in connect
    raise ConnectionError(self._error_message(e))
redis.exceptions.ConnectionError: Error 111 connecting to localhost:6379. Connection refused.

During handling of the above exception, another exception occurred:

Traceback (most recent call last):
  File "/usr/local/lib/python3.6/dist-packages/redis/connection.py", line 439, in connect
    sock = self._connect()
  File "/usr/local/lib/python3.6/dist-packages/redis/connection.py", line 494, in _connect
    raise err
  File "/usr/local/lib/python3.6/dist-packages/redis/connection.py", line 482, in _connect
    sock.connect(socket_address)
ConnectionRefusedError: [Errno 111] Connection refused

During handling of the above exception, another exception occurred:

Traceback (most recent call last):
  File "/usr/local/lib/python3.6/dist-packages/twisted/internet/defer.py", line 1418, in _inlineCallbacks
    result = g.send(result)
  File "/usr/local/lib/python3.6/dist-packages/scrapy/core/downloader/middleware.py", line 38, in process_request
    response = yield method(request=request, spider=spider)
  File "/home/jiangjin/桌面/xxoovideo/xxoovideo/middlewares.py", line 17, in process_request
    if self.bf.isContains(request.url):
  File "/home/jiangjin/桌面/xxoovideo/xxoovideo/tool/bloomfulter.py", line 50, in isContains
    ret = ret & self.server.getbit(name, loc)
  File "/usr/local/lib/python3.6/dist-packages/redis/client.py", line 894, in getbit
    return self.execute_command('GETBIT', name, offset)
  File "/usr/local/lib/python3.6/dist-packages/redis/client.py", line 578, in execute_command
    connection.send_command(*args)
  File "/usr/local/lib/python3.6/dist-packages/redis/connection.py", line 563, in send_command
    self.send_packed_command(self.pack_command(*args))
  File "/usr/local/lib/python3.6/dist-packages/redis/connection.py", line 538, in send_packed_command
    self.connect()
  File "/usr/local/lib/python3.6/dist-packages/redis/connection.py", line 442, in connect
    raise ConnectionError(self._error_message(e))
redis.exceptions.ConnectionError: Error 111 connecting to localhost:6379. Connection refused.
2020-02-08 23:35:36 [scrapy.core.engine] INFO: Closing spider (finished)
2020-02-08 23:35:36 [scrapy.statscollectors] INFO: Dumping Scrapy stats:
{'downloader/exception_count': 45,
 'downloader/exception_type_count/redis.exceptions.ConnectionError': 45,
 'downloader/request_bytes': 1101,
 'downloader/request_count': 2,
 'downloader/request_method_count/GET': 2,
 'downloader/response_bytes': 20627,
 'downloader/response_count': 2,
 'downloader/response_status_count/200': 2,
 'elapsed_time_seconds': 3.58715,
 'finish_reason': 'finished',
 'finish_time': datetime.datetime(2020, 2, 8, 15, 35, 36, 853375),
 'log_count/DEBUG': 2,
 'log_count/ERROR': 46,
 'log_count/INFO': 10,
 'memusage/max': 53592064,
 'memusage/startup': 53592064,
 'request_depth_max': 2,
 'response_received_count': 2,
 'scheduler/dequeued': 47,
 'scheduler/dequeued/memory': 47,
 'scheduler/enqueued': 47,
 'scheduler/enqueued/memory': 47,
 'spider_exceptions/TypeError': 1,
 'start_time': datetime.datetime(2020, 2, 8, 15, 35, 33, 266225)}
2020-02-08 23:35:36 [scrapy.core.engine] INFO: Spider closed (finished)
[]
